Workbook

Sheet Information Sheet
J5: Estimated Cost Analysis
K7: Received | L7: Issued | M7: Remaining
J8: Food and Water | K8: ='Food & Water '!BQ10 -> 0 | L8: ='Food & Water '!BR10 -> 0 | M8: ='Food & Water '!BS10 -> 0
J9: Medical Supplies | K9: ='Medical Supplies '!BQ130 -> 11950200 | L9: ='Medical Supplies '!BR130 -> 230342.43 | M9: ='Medical Supplies '!BS130 -> 11719858
C10: NATIONAL STAGING CENTRE INVENTORY SYSTEM | J10: Shelter and NFI | K10: =#REF! -> #REF! | L10: =#REF! -> #REF! | M10: =#REF! -> #REF!
J11: Hygiene and Sanitation | K11: ='Hygiene and Sanitation'!BQ29 -> 0 | L11: ='Hygiene and Sanitation'!BR29 -> 0 | M11: ='Hygiene and Sanitation'!BS29 -> 0
J12: Logs and Engr Eqpt | K12: ='Logistics & Engineering Equipme'!BQ28 -> 400665 | L12: ='Logistics & Engineering Equipme'!BR28 -> 102994 | M12: ='Logistics & Engineering Equipme'!BS28 -> 297671
J13: Totals | K13: =SUM(K8:K12) -> #REF! | L13: =SUM(L8:L12) -> #REF! | M13: =SUM(M8:M12) -> #REF!
C29: National Staging Centres | D29: Abbreviations | E29: Address | H29: Point of Contact
C31: Kingston Wharf | D31: KW | E31: 195 Second Street Kingston 13, Newport West, Jamaica | H31: Capt S CORNWALL
C32: Marcus Garvey | D32: MG | E32: 80 Marcus Garvey Drive, Kingston | H32: Lt S WILLIAMS
C33: IAM Jet Centre | D33: MOBAY | E33: Burke Barracks, Montego Bay | H33: Lt S SCOTT
C36: Distribution Hubs
C37: St Elizabeth- Black River | D37: 1
C38: Trelawny - Multi Purpose Stadium | D38: 1
C39: St James- Burke Barracks | D39: 1
C40: Hanover - Lucea | D40: 1
C41: Westmoreland- Frome | D41: 1
C46: Colors
D47: ITEMS BEING CHECKED

Sheet Food & Water 
A1: Description of items | B1: Unit | C1: Total Quantity Received | D1: Total Quantity Issued | E1: Quantity in store | F1: Location | G1: 45960 | I1: 45961 | K1: 45962 | M1: 45963 | O1: 45964 | Q1: 45965 | S1: 45966 | U1: 45967 | W1: 45968 | Y1: 45969 | AA1: 45970 | AC1: 45971 | AE1: 45972 | AG1: 45973 | AI1: 45974 | AK1: 45975 | AM1: 45976 | AO1: 45977 | AQ1: 45978 | AS1: 45979 | AU1: 45980 | AW1: 45981 | AY1: 45982 | BA1: 45983 | BC1: 45984 | BE1: 45985 | BG1: 45986 | BI1: 45987 | BK1: 45988 | BM1: 45989 | BO1: Quantity in Store | BP1: Unit Cost(USD) | BQ1: Total Cost (USD) | BR1: Issued (USD) | BS1: Balance (USD)
G2: Received | H2: Issue | I2: Received | J2: Issue | K2: Received | L2: Issue | M2: Received | N2: Issue | O2: Received | P2: Issue | Q2: Received | R2: Issue | S2: Received | T2: Issue | U2: Received | V2: Issue | W2: Received | X2: Issue | Y2: Received | Z2: Issue | AA2: Received | AB2: Issue | AC2: Received | AD2: Issue | AE2: Received | AF2: Issue | AG2: Received | AH2: Issue | AI2: Received | AJ2: Issue | AK2: Received | AL2: Issue | AM2: Received | AN2: Issue | AO2: Received | AP2: Issue | AQ2: Received | AR2: Issue | AS2: Received | AT2: Issue | AU2: Received | AV2: Issue | AW2: Received | AX2: Issue | AY2: Received | AZ2: Issue | BA2: Received | BB2: Issue | BC2: Received | BD2: Issue | BE2: Received | BF2: Issue | BG2: Received | BH2: Issue | BI2: Received | BJ2: Issue | BK2: Received | BL2: Issue | BM2: Received | BN2: Issue
A3: Food Packages | B3: ea | C3: =SUM(G3+I3+K3+M3+O3+Q3+S3+U3+W3+Y3+AA3+AC3+AE3+AG3+AI3+AK3+AM3+AO3+AQ3+AS3+AU3+AW3+AY3+BA3+BC3+BE3+BG3+BI3+BK3+BM3) -> 73706 | D3: =H3+J3+L3+N3+P3+R3+T3+V3+X3+Z3+AB3+AD3+AF3+AH3+AJ3+AL3+AN3+AP3+AR3+AT3+AV3+AX3+AZ3+BB3+BD3+BF3+BH3+BJ3+BL3+BN3 -> 64420 | E3: =C3-D3 -> 9286 | F3: KW | G3: 900 | H3: =827 -> 827 | I3: 0 | J3: 30 | K3: 70 | L3: 0 | M3: 0 | N3: =70+43 -> 113 | O3: 0 | P3: 0 | Q3: 69080 | R3: 0 | S3: 1100 | T3: =1100+2500 -> 3600 | U3: 0 | V3: =2200+1800+10+1200 -> 5210 | W3: 0 | X3: =2000+90 -> 2090 | Y3: 0 | Z3: =1600+2000+2000+2000+1800+30 -> 9430 | AA3: 0 | AB3: =2000+2000+2000+2000+6000 -> 14000 | AC3: 0 | AD3: 0 | AE3: =740+1816 -> 2556 | AF3: =2200+2200+2200+2000+2200+2200 -> 13000 | AG3: 0 | AH3: 316 | AI3: 0 | AJ3: =550+1800+250+112 -> 2712 | AK3: 0 | AL3: =63+116+43+3+15 -> 240 | AM3: 0 | AN3: =200+200+200 -> 600 | AO3: 0 | AP3: 0 | AQ3: 0 | AR3: =1350+2600 -> 3950 | AS3: 0 | AT3: 0 | AU3: 0 | AV3: 200 | AW3: 0 | AX3: =1500+200 -> 1700 | AY3: 0 | AZ3: =195+600 -> 795 | BA3: 0 | BB3: 2000 | BC3: 0 | BD3: 0 | BE3: 0 | BF3: 1650 | BG3: 0 | BH3: =450 -> 450 | BI3: 0 | BJ3: 0 | BK3: 0 | BL3: =755+752 -> 1507 | BM3: 0 | BN3: 0 | BO3: =G3-H3+I3-J3+K3-L3+M3-N3+O3-P3+Q3-R3+S3-T3+U3-V3+W3-X3+Y3-Z3+AA3-AB3+AC3-AD3+AE3-AF3+AG3-AH3+AI3-AJ3+AK3-AL3+AM3-AN3+AO3-AP3+AQ3-AR3+AS3-AT3+AU3-AV3+AW3-AX3+AY3-AZ3+BA3-+BB3+BC3-BD3+BE3-BF3+BG3-BH3+BI3-BJ3+BK3-BL3+BM3-BN3 -> 9286 | BP3: 25 | BQ3: =C3*BP3 -> 1842650 | BR3: =D3*BP3 -> 1610500 | BS3: =E3*BP3 -> 232150
A4: Oil (600 ml) | B4: ea | C4: =SUM(G4+I4+K4+M4+O4+Q4+S4+U4+W4+Y4+AA4+AC4+AE4+AG4+AI4+AK4+AM4+AO4+AQ4+AS4+AU4+AW4+AY4+BA4+BC4+BE4+BG4+BI4+BK4+BM4) -> 996 | D4: =H4+J4+L4+N4+P4+R4+T4+V4+X4+Z4+AB4+AD4+AF4+AH4+AJ4+AL4+AN4+AP4+AR4+AT4+AV4+AX4+AZ4+BB4+BD4+BF4+BH4+BJ4+BL4+BN4 -> 996 | E4: =C4-D4 -> 0 | G4: 996 | H4: 0 | I4: 0 | J4: 69 | K4: 0 | L4: 0 | M4: 0 | N4: 0 | O4: 0 | P4: 927 | Q4: 0 | R4: 0 | S4: 0 | T4: 0 | U4: 0 | V4: 0 | W4: 0 | X4: 0 | Y4: 0 | Z4: 0 | AA4: 0 | AB4: 0 | AC4: 0 | AD4: 0 | AE4: 0 | AF4: 0 | AG4: 0 | AH4: 0 | AI4: 0 | AJ4: 0 | AK4: 0 | AL4: 0 | AM4: 0 | AN4: 0 | AO4: 0 | AP4: 0 | AQ4: 0 | AR4: 0 | AS4: 0 | AT4: 0 | AU4: 0 | AV4: 0 | AW4: 0 | AX4: 0 | AY4: 0 | AZ4: 0 | BA4: 0 | BB4: 0 | BC4: 0 | BD4: 0 | BE4: 0 | BF4: 0 | BG4: 0 | BH4: 0 | BI4: 0 | BJ4: 0 | BK4: 0 | BL4: 0 | BM4: 0 | BN4: 0 | BO4: =G4-H4+I4-J4+K4-L4+M4-N4+O4-P4+Q4-R4+S4-T4+U4-V4+W4-X4+Y4-Z4+AA4-AB4+AC4-AD4+AE4-AF4+AG4-AH4+AI4-AJ4+AK4-AL4+AM4-AN4+AO4-AP4+AQ4-AR4+AS4-AT4+AU4-AV4+AW4-AX4+AY4-AZ4+BA4-+BB4+BC4-BD4+BE4-BF4+BG4-BH4+BI4-BJ4+BK4-BL4+BM4-BN4 -> 0 | BP4: 1.5 | BQ4: =C4*BP4 -> 1494 | BR4: =D4*BP4 -> 1494 | BS4: =E4*BP4 -> 0
A5: Bottle Water (12 per case) | B5: ea | C5: =SUM(G5+I5+K5+M5+O5+Q5+S5+U5+W5+Y5+AA5+AC5+AE5+AG5+AI5+AK5+AM5+AO5+AQ5+AS5+AU5+AW5+AY5+BA5+BC5+BE5+BG5+BI5+BK5+BM5) -> 41931 | D5: =H5+J5+L5+N5+P5+R5+T5+V5+X5+Z5+AB5+AD5+AF5+AH5+AJ5+AL5+AN5+AP5+AR5+AT5+AV5+AX5+AZ5+BB5+BD5+BF5+BH5+BJ5+BL5+BN5 -> 41201 | E5: =C5-D5 -> 730 | F5: MG | G5: 0 | H5: 0 | I5: 0 | J5: 0 | K5: 0 | L5: 0 | M5: 0 | N5: 0 | O5: =15960+16632 -> 32592 | P5: 15960 | Q5: 4918 | R5: 0 | S5: 0 | T5: =2400+3600 -> 6000 | U5: 0 | V5: 7200 | W5: 0 | X5: 0 | Y5: 0 | Z5: 360 | AA5: 0 | AB5: 7200 | AC5: 0 | AD5: 0 | AE5: 2064 | AF5: 0 | AG5: 0 | AH5: 0 | AI5: 0 | AJ5: 0 | AK5: 0 | AL5: 1200 | AM5: 2357 | AN5: 0 | AO5: 0 | AP5: 0 | AQ5: 0 | AR5: =1152+1173 -> 2325 | AS5: 0 | AT5: 0 | AU5: 0 | AV5: 0 | AW5: 0 | AX5: =836+120 -> 956 | AY5: 0 | AZ5: 0 | BA5: 0 | BB5: 0 | BC5: 0 | BD5: 0 | BE5: 0 | BF5: 0 | BG5: 0 | BH5: 0 | BI5: 0 | BJ5: 0 | BK5: 0 | BL5: 0 | BM5: 0 | BN5: 0 | BO5: =G5-H5+I5-J5+K5-L5+M5-N5+O5-P5+Q5-R5+S5-T5+U5-V5+W5-X5+Y5-Z5+AA5-AB5+AC5-AD5+AE5-AF5+AG5-AH5+AI5-AJ5+AK5-AL5+AM5-AN5+AO5-AP5+AQ5-AR5+AS5-AT5+AU5-AV5+AW5-AX5+AY5-AZ5+BA5-+BB5+BC5-BD5+BE5-BF5+BG5-BH5+BI5-BJ5+BK5-BL5+BM5-BN5 -> 730 | BP5: 0.03 | BQ5: =C5*BP5 -> 1257.93 | BR5: =D5*BP5 -> 1236.03 | BS5: =E5*BP5 -> 21.9
A6: Bottle Water (5 Gal ) | B6: ea | C6: =SUM(G6+I6+K6+M6+O6+Q6+S6+U6+W6+Y6+AA6+AC6+AE6+AG6+AI6+AK6+AM6+AO6+AQ6+AS6+AU6+AW6+AY6+BA6+BC6+BE6+BG6+BI6+BK6+BM6) -> 100 | D6: =H6+J6+L6+N6+P6+R6+T6+V6+X6+Z6+AB6+AD6+AF6+AH6+AJ6+AL6+AN6+AP6+AR6+AT6+AV6+AX6+AZ6+BB6+BD6+BF6+BH6+BJ6+BL6+BN6 -> 20 | E6: =C6-D6 -> 80 | F6: MG | G6: 0 | H6: 0 | I6: 0 | J6: 0 | K6: 0 | L6: 0 | M6: 0 | N6: 0 | O6: 0 | P6: 0 | Q6: 0 | R6: 0 | S6: 0 | T6: 0 | U6: 0 | V6: 0 | W6: 0 | X6: 0 | Y6: 0 | Z6: 0 | AA6: 0 | AB6: 0 | AC6: 0 | AD6: 0 | AE6: 0 | AF6: 0 | AG6: 0 | AH6: 0 | AI6: 0 | AJ6: 0 | AK6: 0 | AL6: 0 | AM6: 0 | AN6: 0 | AO6: 0 | AP6: 0 | AQ6: 0 | AR6: 0 | AS6: 0 | AT6: 0 | AU6: 100 | AV6: 0 | AW6: 0 | AX6: 20 | AY6: 0 | AZ6: 0 | BA6: 0 | BB6: 0 | BC6: 0 | BD6: 0 | BE6: 0 | BF6: 0 | BG6: 0 | BH6: 0 | BI6: 0 | BJ6: 0 | BK6: 0 | BL6: 0 | BM6: 0 | BN6: 0 | BO6: =G6-H6+I6-J6+K6-L6+M6-N6+O6-P6+Q6-R6+S6-T6+U6-V6+W6-X6+Y6-Z6+AA6-AB6+AC6-AD6+AE6-AF6+AG6-AH6+AI6-AJ6+AK6-AL6+AM6-AN6+AO6-AP6+AQ6-AR6+AS6-AT6+AU6-AV6+AW6-AX6+AY6-AZ6+BA6-+BB6+BC6-BD6+BE6-BF6+BG6-BH6+BI6-BJ6+BK6-BL6+BM6-BN6 -> 80
A7: Meals Ready to Eat | B7: ea | C7: =SUM(G7+I7+K7+M7+O7+Q7+S7+U7+W7+Y7+AA7+AC7+AE7+AG7+AI7+AK7+AM7+AO7+AQ7+AS7+AU7+AW7+AY7+BA7+BC7+BE7+BG7+BI7+BK7+BM7) -> 1544 | D7: =H7+J7+L7+N7+P7+R7+T7+V7+X7+Z7+AB7+AD7+AF7+AH7+AJ7+AL7+AN7+AP7+AR7+AT7+AV7+AX7+AZ7+BB7+BD7+BF7+BH7+BJ7+BL7+BN7 -> 1384 | E7: =C7-D7 -> 160 | F7: MG | G7: 0 | H7: 0 | I7: 0 | J7: 0 | K7: 0 | L7: 0 | M7: 0 | N7: 0 | O7: 864 | P7: 0 | Q7: 0 | R7: 0 | S7: 0 | T7: 864 | U7: 680 | V7: 0 | W7: 0 | X7: 0 | Y7: 0 | Z7: 160 | AA7: 0 | AB7: 0 | AC7: 0 | AD7: 0 | AE7: 0 | AF7: 0 | AG7: 0 | AH7: 300 | AI7: 0 | AJ7: 0 | AK7: 0 | AL7: 0 | AM7: 0 | AN7: 0 | AO7: 0 | AP7: 0 | AQ7: 0 | AR7: 0 | AS7: 0 | AT7: 0 | AU7: 0 | AV7: 0 | AW7: 0 | AX7: 0 | AY7: 0 | AZ7: 0 | BA7: 0 | BB7: 0 | BC7: 0 | BD7: 0 | BE7: 0 | BF7: 0 | BG7: 0 | BH7: 0 | BI7: 0 | BJ7: =20+20+20 -> 60 | BK7: 0 | BL7: 0 | BM7: 0 | BN7: 0 | BO7: =G7-H7+I7-J7+K7-L7+M7-N7+O7-P7+Q7-R7+S7-T7+U7-V7+W7-X7+Y7-Z7+AA7-AB7+AC7-AD7+AE7-AF7+AG7-AH7+AI7-AJ7+AK7-AL7+AM7-AN7+AO7-AP7+AQ7-AR7+AS7-AT7+AU7-AV7+AW7-AX7+AY7-AZ7+BA7-+BB7+BC7-BD7+BE7-BF7+BG7-BH7+BI7-BJ7+BK7-BL7+BM7-BN7 -> 160 | BP7: 6 | BQ7: =C7*BP7 -> 9264 | BR7: =D7*BP7 -> 8304 | BS7: =E7*BP7 -> 960
A8: Water Purification Tablets (108,000 per box) | B8: ea | C8: =SUM(G8+I8+K8+M8+O8+Q8+S8+U8+W8+Y8+AA8+AC8+AE8+AG8+AI8+AK8+AM8+AO8+AQ8+AS8+AU8+AW8+AY8+BA8+BC8+BE8+BG8+BI8+BK8+BM8) -> 4428000 | D8: =H8+J8+L8+N8+P8+R8+T8+V8+X8+Z8+AB8+AD8+AF8+AH8+AJ8+AL8+AN8+AP8+AR8+AT8+AV8+AX8+AZ8+BB8+BD8+BF8+BH8+BJ8+BL8+BN8 -> 1291000 | E8: =C8-D8 -> 3137000 | F8: MG | G8: 0 | H8: 0 | I8: 0 | J8: 0 | K8: 0 | L8: 0 | M8: 0 | N8: 0 | O8: 0 | P8: 0 | Q8: 0 | R8: 0 | S8: 0 | T8: 0 | U8: 4104000 | V8: 0 | W8: 0 | X8: 0 | Y8: 0 | Z8: 0 | AA8: 0 | AB8: 0 | AC8: 0 | AD8: 0 | AE8: 0 | AF8: 0 | AG8: 0 | AH8: 750000 | AI8: 0 | AJ8: 0 | AK8: 0 | AL8: 0 | AM8: =108000+108000+108000 -> 324000 | AN8: 0 | AO8: 0 | AP8: 0 | AQ8: 0 | AR8: 0 | AS8: 0 | AT8: 0 | AU8: 0 | AV8: 0 | AW8: 0 | AX8: 108000 | AY8: 0 | AZ8: =108000+1000 -> 109000 | BA8: 0 | BB8: 0 | BC8: 0 | BD8: 0 | BE8: 0 | BF8: 0 | BG8: 0 | BH8: 0 | BI8: 0 | BJ8: =108000+108000+108000 -> 324000 | BK8: 0 | BL8: 0 | BM8: 0 | BN8: 0 | BO8: =G8-H8+I8-J8+K8-L8+M8-N8+O8-P8+Q8-R8+S8-T8+U8-V8+W8-X8+Y8-Z8+AA8-AB8+AC8-AD8+AE8-AF8+AG8-AH8+AI8-AJ8+AK8-AL8+AM8-AN8+AO8-AP8+AQ8-AR8+AS8-AT8+AU8-AV8+AW8-AX8+AY8-AZ8+BA8-+BB8+BC8-BD8+BE8-BF8+BG8-BH8+BI8-BJ8+BK8-BL8+BM8-BN8 -> 3137000 | BP8: 0.1 | BQ8: =C8*BP8 -> 442800 | BR8: =D8*BP8 -> 129100 | BS8: =E8*BP8 -> 313700
A9: Cup Soup | B9: cases | C9: =SUM(G9+I9+K9+M9+O9+Q9+S9+U9+W9+Y9+AA9+AC9+AE9+AG9+AI9+AK9+AM9+AO9+AQ9+AS9+AU9+AW9+AY9+BA9+BC9+BE9+BG9+BI9+BK9+BM9) -> 52 | D9: =H9+J9+L9+N9+P9+R9+T9+V9+X9+Z9+AB9+AD9+AF9+AH9+AJ9+AL9+AN9+AP9+AR9+AT9+AV9+AX9+AZ9+BB9+BD9+BF9+BH9+BJ9+BL9+BN9 -> 52 | E9: =C9-D9 -> 0 | G9: 0 | H9: 0 | I9: 0 | J9: 0 | K9: 0 | L9: 0 | M9: 0 | N9: 0 | O9: 0 | P9: 0 | Q9: 0 | R9: 0 | S9: 0 | T9: 0 | U9: 0 | V9: 0 | W9: 0 | X9: 0 | Y9: 0 | Z9: 0 | AA9: 0 | AB9: 0 | AC9: 0 | AD9: 0 | AE9: 52 | AF9: 0 | AG9: 0 | AH9: 0 | AI9: 0 | AJ9: 0 | AK9: 0 | AL9: 0 | AM9: 0 | AN9: 0 | AO9: 0 | AP9: 0 | AQ9: 0 | AR9: 0 | AS9: 0 | AT9: 0 | AU9: 0 | AV9: 0 | AW9: 0 | AX9: 52 | AY9: 0 | AZ9: 0 | BA9: 0 | BB9: 0 | BC9: 0 | BD9: 0 | BE9: 0 | BF9: 0 | BG9: 0 | BH9: 0 | BI9: 0 | BJ9: 0 | BK9: 0 | BL9: 0 | BM9: 0 | BN9: 0 | BO9: =G9-H9+I9-J9+K9-L9+M9-N9+O9-P9+Q9-R9+S9-T9+U9-V9+W9-X9+Y9-Z9+AA9-AB9+AC9-AD9+AE9-AF9+AG9-AH9+AI9-AJ9+AK9-AL9+AM9-AN9+AO9-AP9+AQ9-AR9+AS9-AT9+AU9-AV9+AW9-AX9+AY9-AZ9+BA9-+BB9+BC9-BD9+BE9-BF9+BG9-BH9+BI9-BJ9+BK9-BL9+BM9-BN9 -> 0 | BP9: 14 | BQ9: =C9*BP9 -> 728 | BR9: =D9*BP9 -> 728 | BS9: =E9*BP9 -> 0
A10: Mysimilac Sml | B10: ea | C10: =SUM(G10+I10+K10+M10+O10+Q10+S10+U10+W10+Y10+AA10+AC10+AE10+AG10+AI10+AK10+AM10+AO10+AQ10+AS10+AU10+AW10+AY10+BA10+BC10+BE10+BG10+BI10+BK10+BM10) -> 60 | D10: =H10+J10+L10+N10+P10+R10+T10+V10+X10+Z10+AB10+AD10+AF10+AH10+AJ10+AL10+AN10+AP10+AR10+AT10+AV10+AX10+AZ10+BB10+BD10+BF10+BH10+BJ10+BL10+BN10 -> 58 | E10: =C10-D10 -> 2 | F10: Mobay | G10: 0 | H10: 0 | I10: 0 | J10: 0 | K10: 0 | L10: 0 | M10: 0 | N10: 0 | O10: 0 | P10: 0 | Q10: 0 | R10: 0 | S10: 0 | T10: 0 | U10: 0 | V10: 0 | W10: 0 | X10: 0 | Y10: 0 | Z10: 0 | AA10: 0 | AB10: 0 | AC10: 0 | AD10: 0 | AE10: 0 | AF10: 0 | AG10: 0 | AH10: 0 | AI10: 60 | AJ10: 0 | AK10: 0 | AL10: 0 | AM10: 0 | AN10: 0 | AO10: 0 | AP10: 0 | AQ10: 0 | AR10: =29+29 -> 58 | AS10: 0 | AT10: 0 | AU10: 0 | AV10: 0 | AW10: 0 | AX10: 0 | AY10: 0 | AZ10: 0 | BA10: 0 | BB10: 0 | BC10: 0 | BD10: 0 | BE10: 0 | BF10: 0 | BG10: 0 | BH10: 0 | BI10: 0 | BJ10: 0 | BK10: 0 | BL10: 0 | BM10: 0 | BN10: 0 | BO10: =G10-H10+I10-J10+K10-L10+M10-N10+O10-P10+Q10-R10+S10-T10+U10-V10+W10-X10+Y10-Z10+AA10-AB10+AC10-AD10+AE10-AF10+AG10-AH10+AI10-AJ10+AK10-AL10+AM10-AN10+AO10-AP10+AQ10-AR10+AS10-AT10+AU10-AV10+AW10-AX10+AY10-AZ10+BA10-+BB10+BC10-BD10+BE10-BF10+BG10-BH10+BI10-BJ10+BK10-BL10+BM10-BN10 -> 2 | BP10: 0 | BQ10: =C10*BP10 -> 0 | BR10: =D10*BP10 -> 0 | BS10: =E10*BP10 -> 0
A11: Parents Choice Formula | B11: ea | C11: =SUM(G11+I11+K11+M11+O11+Q11+S11+U11+W11+Y11+AA11+AC11+AE11+AG11+AI11+AK11+AM11+AO11+AQ11+AS11+AU11+AW11+AY11+BA11+BC11+BE11+BG11+BI11+BK11+BM11) -> 3 | D11: =H11+J11+L11+N11+P11+R11+T11+V11+X11+Z11+AB11+AD11+AF11+AH11+AJ11+AL11+AN11+AP11+AR11+AT11+AV11+AX11+AZ11+BB11+BD11+BF11+BH11+BJ11+BL11+BN11 -> 3 | E11: =C11-D11 -> 0 | G11: 0 | H11: 0 | I11: 0 | J11: 0 | K11: 0 | L11: 0 | M11: 0 | N11: 0 | O11: 0 | P11: 0 | Q11: 0 | R11: 0 | S11: 0 | T11: 0 | U11: 0 | V11: 0 | W11: 0 | X11: 0 | Y11: 0 | Z11: 0 | AA11: 0 | AB11: 0 | AC11: 0 | AD11: 0 | AE11: 0 | AF11: 0 | AG11: 0 | AH11: 0 | AI11: 3 | AJ11: 0 | AK11: 0 | AL11: 0 | AM11: 0 | AN11: 0 | AO11: 0 | AP11: 0 | AQ11: 0 | AR11: 3 | AS11: 0 | AT11: 0 | AU11: 0 | AV11: 0 | AW11: 0 | AX11: 0 | AY11: 0 | AZ11: 0 | BA11: 0 | BB11: 0 | BC11: 0 | BD11: 0 | BE11: 0 | BF11: 0 | BG11: 0 | BH11: 0 | BI11: 0 | BJ11: 0 | BK11: 0 | BL11: 0 | BM11: 0 | BN11: 0 | BO11: =G11-H11+I11-J11+K11-L11+M11-N11+O11-P11+Q11-R11+S11-T11+U11-V11+W11-X11+Y11-Z11+AA11-AB11+AC11-AD11+AE11-AF11+AG11-AH11+AI11-AJ11+AK11-AL11+AM11-AN11+AO11-AP11+AQ11-AR11+AS11-AT11+AU11-AV11+AW11-AX11+AY11-AZ11+BA11-+BB11+BC11-BD11+BE11-BF11+BG11-BH11+BI11-BJ11+BK11-BL11+BM11-BN11 -> 0 | BP11: 0 | BQ11: =C11*BP11 -> 0 | BR11: =D11*BP11 -> 0 | BS11: =E11*BP11 -> 0
A12: Nestle Nido Formula | B12: ea | C12: =SUM(G12+I12+K12+M12+O12+Q12+S12+U12+W12+Y12+AA12+AC12+AE12+AG12+AI12+AK12+AM12+AO12+AQ12+AS12+AU12+AW12+AY12+BA12+BC12+BE12+BG12+BI12+BK12+BM12) -> 2 | D12: =H12+J12+L12+N12+P12+R12+T12+V12+X12+Z12+AB12+AD12+AF12+AH12+AJ12+AL12+AN12+AP12+AR12+AT12+AV12+AX12+AZ12+BB12+BD12+BF12+BH12+BJ12+BL12+BN12 -> 2 | E12: =C12-D12 -> 0 | G12: 0 | H12: 0 | I12: 0 | J12: 0 | K12: 0 | L12: 0 | M12: 0 | N12: 0 | O12: 0 | P12: 0 | Q12: 0 | R12: 0 | S12: 0 | T12: 0 | U12: 0 | V12: 0 | W12: 0 | X12: 0 | Y12: 0 | Z12: 0 | AA12: 0 | AB12: 0 | AC12: 0 | AD12: 0 | AE12: 0 | AF12: 0 | AG12: 0 | AH12: 0 | AI12: 2 | AJ12: 0 | AK12: 0 | AL12: 0 | AM12: 0 | AN12: 0 | AO12: 0 | AP12: 0 | AQ12: 0 | AR12: 2 | AS12: 0 | AT12: 0 | AU12: 0 | AV12: 0 | AW12: 0 | AX12: 0 | AY12: 0 | AZ12: 0 | BA12: 0 | BB12: 0 | BC12: 0 | BD12: 0 | BE12: 0 | BF12: 0 | BG12: 0 | BH12: 0 | BI12: 0 | BJ12: 0 | BK12: 0 | BL12: 0 | BM12: 0 | BN12: 0 | BO12: =G12-H12+I12-J12+K12-L12+M12-N12+O12-P12+Q12-R12+S12-T12+U12-V12+W12-X12+Y12-Z12+AA12-AB12+AC12-AD12+AE12-AF12+AG12-AH12+AI12-AJ12+AK12-AL12+AM12-AN12+AO12-AP12+AQ12-AR12+AS12-AT12+AU12-AV12+AW12-AX12+AY12-AZ12+BA12-+BB12+BC12-BD12+BE12-BF12+BG12-BH12+BI12-BJ12+BK12-BL12+BM12-BN12 -> 0 | BP12: 0 | BQ12: =C12*BP12 -> 0 | BR12: =D12*BP12 -> 0 | BS12: =E12*BP12 -> 0
A13: Similac | B13: ea | C13: =SUM(G13+I13+K13+M13+O13+Q13+S13+U13+W13+Y13+AA13+AC13+AE13+AG13+AI13+AK13+AM13+AO13+AQ13+AS13+AU13+AW13+AY13+BA13+BC13+BE13+BG13+BI13+BK13+BM13) -> 3 | D13: =H13+J13+L13+N13+P13+R13+T13+V13+X13+Z13+AB13+AD13+AF13+AH13+AJ13+AL13+AN13+AP13+AR13+AT13+AV13+AX13+AZ13+BB13+BD13+BF13+BH13+BJ13+BL13+BN13 -> 3 | E13: =C13-D13 -> 0 | G13: 0 | H13: 0 | I13: 0 | J13: 0 | K13: 0 | L13: 0 | M13: 0 | N13: 0 | O13: 0 | P13: 0 | Q13: 0 | R13: 0 | S13: 0 | T13: 0 | U13: 0 | V13: 0 | W13: 0 | X13: 0 | Y13: 0 | Z13: 0 | AA13: 0 | AB13: 0 | AC13: 0 | AD13: 0 | AE13: 0 | AF13: 0 | AG13: 0 | AH13: 0 | AI13: 3 | AJ13: 0 | AK13: 0 | AL13: 0 | AM13: 0 | AN13: 0 | AO13: 0 | AP13: 0 | AQ13: 0 | AR13: 3 | AS13: 0 | AT13: 0 | AU13: 0 | AV13: 0 | AW13: 0 | AX13: 0 | AY13: 0 | AZ13: 0 | BA13: 0 | BB13: 0 | BC13: 0 | BD13: 0 | BE13: 0 | BF13: 0 | BG13: 0 | BH13: 0 | BI13: 0 | BJ13: 0 | BK13: 0 | BL13: 0 | BM13: 0 | BN13: 0 | BO13: =G13-H13+I13-J13+K13-L13+M13-N13+O13-P13+Q13-R13+S13-T13+U13-V13+W13-X13+Y13-Z13+AA13-AB13+AC13-AD13+AE13-AF13+AG13-AH13+AI13-AJ13+AK13-AL13+AM13-AN13+AO13-AP13+AQ13-AR13+AS13-AT13+AU13-AV13+AW13-AX13+AY13-AZ13+BA13-+BB13+BC13-BD13+BE13-BF13+BG13-BH13+BI13-BJ13+BK13-BL13+BM13-BN13 -> 0 | BP13: 0 | BQ13: =C13*BP13 -> 0 | BR13: =D13*BP13 -> 0 | BS13: =E13*BP13 -> 0
A14: Enfamil | B14: ea | C14: =SUM(G14+I14+K14+M14+O14+Q14+S14+U14+W14+Y14+AA14+AC14+AE14+AG14+AI14+AK14+AM14+AO14+AQ14+AS14+AU14+AW14+AY14+BA14+BC14+BE14+BG14+BI14+BK14+BM14) -> 2 | D14: =H14+J14+L14+N14+P14+R14+T14+V14+X14+Z14+AB14+AD14+AF14+AH14+AJ14+AL14+AN14+AP14+AR14+AT14+AV14+AX14+AZ14+BB14+BD14+BF14+BH14+BJ14+BL14+BN14 -> 2 | E14: =C14-D14 -> 0 | G14: 0 | H14: 0 | I14: 0 | J14: 0 | K14: 0 | L14: 0 | M14: 0 | N14: 0 | O14: 0 | P14: 0 | Q14: 0 | R14: 0 | S14: 0 | T14: 0 | U14: 0 | V14: 0 | W14: 0 | X14: 0 | Y14: 0 | Z14: 0 | AA14: 0 | AB14: 0 | AC14: 0 | AD14: 0 | AE14: 0 | AF14: 0 | AG14: 0 | AH14: 0 | AI14: 2 | AJ14: 0 | AK14: 0 | AL14: 0 | AM14: 0 | AN14: 0 | AO14: 0 | AP14: 0 | AQ14: 0 | AR14: 2 | AS14: 0 | AT14: 0 | AU14: 0 | AV14: 0 | AW14: 0 | AX14: 0 | AY14: 0 | AZ14: 0 | BA14: 0 | BB14: 0 | BC14: 0 | BD14: 0 | BE14: 0 | BF14: 0 | BG14: 0 | BH14: 0 | BI14: 0 | BJ14: 0 | BK14: 0 | BL14: 0 | BM14: 0 | BN14: 0 | BO14: =G14-H14+I14-J14+K14-L14+M14-N14+O14-P14+Q14-R14+S14-T14+U14-V14+W14-X14+Y14-Z14+AA14-AB14+AC14-AD14+AE14-AF14+AG14-AH14+AI14-AJ14+AK14-AL14+AM14-AN14+AO14-AP14+AQ14-AR14+AS14-AT14+AU14-AV14+AW14-AX14+AY14-AZ14+BA14-+BB14+BC14-BD14+BE14-BF14+BG14-BH14+BI14-BJ14+BK14-BL14+BM14-BN14 -> 0 | BP14: 0 | BQ14: =C14*BP14 -> 0 | BR14: =D14*BP14 -> 0 | BS14: =E14*BP14 -> 0
A15: Mini Similac Formula | B15: ea | C15: =SUM(G15+I15+K15+M15+O15+Q15+S15+U15+W15+Y15+AA15+AC15+AE15+AG15+AI15+AK15+AM15+AO15+AQ15+AS15+AU15+AW15+AY15+BA15+BC15+BE15+BG15+BI15+BK15+BM15) -> 12 | D15: =H15+J15+L15+N15+P15+R15+T15+V15+X15+Z15+AB15+AD15+AF15+AH15+AJ15+AL15+AN15+AP15+AR15+AT15+AV15+AX15+AZ15+BB15+BD15+BF15+BH15+BJ15+BL15+BN15 -> 12 | E15: =C15-D15 -> 0 | G15: 0 | H15: 0 | I15: 0 | J15: 0 | K15: 0 | L15: 0 | M15: 0 | N15: 0 | O15: 0 | P15: 0 | Q15: 0 | R15: 0 | S15: 0 | T15: 0 | U15: 0 | V15: 0 | W15: 0 | X15: 0 | Y15: 0 | Z15: 0 | AA15: 0 | AB15: 0 | AC15: 0 | AD15: 0 | AE15: 0 | AF15: 0 | AG15: 0 | AH15: 0 | AI15: 12 | AJ15: 0 | AK15: 0 | AL15: 0 | AM15: 0 | AN15: 0 | AO15: 0 | AP15: 0 | AQ15: 0 | AR15: 12 | AS15: 0 | AT15: 0 | AU15: 0 | AV15: 0 | AW15: 0 | AX15: 0 | AY15: 0 | AZ15: 0 | BA15: 0 | BB15: 0 | BC15: 0 | BD15: 0 | BE15: 0 | BF15: 0 | BG15: 0 | BH15: 0 | BI15: 0 | BJ15: 0 | BK15: 0 | BL15: 0 | BM15: 0 | BN15: 0 | BO15: =G15-H15+I15-J15+K15-L15+M15-N15+O15-P15+Q15-R15+S15-T15+U15-V15+W15-X15+Y15-Z15+AA15-AB15+AC15-AD15+AE15-AF15+AG15-AH15+AI15-AJ15+AK15-AL15+AM15-AN15+AO15-AP15+AQ15-AR15+AS15-AT15+AU15-AV15+AW15-AX15+AY15-AZ15+BA15-+BB15+BC15-BD15+BE15-BF15+BG15-BH15+BI15-BJ15+BK15-BL15+BM15-BN15 -> 0 | BP15: 0 | BQ15: =C15*BP15 -> 0 | BR15: =D15*BP15 -> 0 | BS15: =E15*BP15 -> 0
A16: Cereal | B16: ea | C16: =SUM(G16+I16+K16+M16+O16+Q16+S16+U16+W16+Y16+AA16+AC16+AE16+AG16+AI16+AK16+AM16+AO16+AQ16+AS16+AU16+AW16+AY16+BA16+BC16+BE16+BG16+BI16+BK16+BM16) -> 2 | D16: =H16+J16+L16+N16+P16+R16+T16+V16+X16+Z16+AB16+AD16+AF16+AH16+AJ16+AL16+AN16+AP16+AR16+AT16+AV16+AX16+AZ16+BB16+BD16+BF16+BH16+BJ16+BL16+BN16 -> 2 | E16: =C16-D16 -> 0 | G16: 0 | H16: 0 | I16: 0 | J16: 0 | K16: 0 | L16: 0 | M16: 0 | N16: 0 | O16: 0 | P16: 0 | Q16: 0 | R16: 0 | S16: 0 | T16: 0 | U16: 0 | V16: 0 | W16: 0 | X16: 0 | Y16: 0 | Z16: 0 | AA16: 0 | AB16: 0 | AC16: 0 | AD16: 0 | AE16: 0 | AF16: 0 | AG16: 0 | AH16: 0 | AI16: 2 | AJ16: 0 | AK16: 0 | AL16: 0 | AM16: 0 | AN16: 0 | AO16: 0 | AP16: 0 | AQ16: 0 | AR16: 2 | AS16: 0 | AT16: 0 | AU16: 0 | AV16: 0 | AW16: 0 | AX16: 0 | AY16: 0 | AZ16: 0 | BA16: 0 | BB16: 0 | BC16: 0 | BD16: 0 | BE16: 0 | BF16: 0 | BG16: 0 | BH16: 0 | BI16: 0 | BJ16: 0 | BK16: 0 | BL16: 0 | BM16: 0 | BN16: 0 | BO16: =G16-H16+I16-J16+K16-L16+M16-N16+O16-P16+Q16-R16+S16-T16+U16-V16+W16-X16+Y16-Z16+AA16-AB16+AC16-AD16+AE16-AF16+AG16-AH16+AI16-AJ16+AK16-AL16+AM16-AN16+AO16-AP16+AQ16-AR16+AS16-AT16+AU16-AV16+AW16-AX16+AY16-AZ16+BA16-+BB16+BC16-BD16+BE16-BF16+BG16-BH16+BI16-BJ16+BK16-BL16+BM16-BN16 -> 0 | BP16: 0 | BQ16: =C16*BP16 -> 0 | BR16: =D16*BP16 -> 0 | BS16: =E16*BP16 -> 0
A17: Dry Whole Milk Lrg | B17: ea | C17: =SUM(G17+I17+K17+M17+O17+Q17+S17+U17+W17+Y17+AA17+AC17+AE17+AG17+AI17+AK17+AM17+AO17+AQ17+AS17+AU17+AW17+AY17+BA17+BC17+BE17+BG17+BI17+BK17+BM17) -> 1 | D17: =H17+J17+L17+N17+P17+R17+T17+V17+X17+Z17+AB17+AD17+AF17+AH17+AJ17+AL17+AN17+AP17+AR17+AT17+AV17+AX17+AZ17+BB17+BD17+BF17+BH17+BJ17+BL17+BN17 -> 1 | E17: =C17-D17 -> 0 | G17: 0 | H17: 0 | I17: 0 | J17: 0 | K17: 0 | L17: 0 | M17: 0 | N17: 0 | O17: 0 | P17: 0 | Q17: 0 | R17: 0 | S17: 0 | T17: 0 | U17: 0 | V17: 0 | W17: 0 | X17: 0 | Y17: 0 | Z17: 0 | AA17: 0 | AB17: 0 | AC17: 0 | AD17: 0 | AE17: 0 | AF17: 0 | AG17: 0 | AH17: 0 | AI17: 1 | AJ17: 0 | AK17: 0 | AL17: 0 | AM17: 0 | AN17: 0 | AO17: 0 | AP17: 0 | AQ17: 0 | AR17: 1 | AS17: 0 | AT17: 0 | AU17: 0 | AV17: 0 | AW17: 0 | AX17: 0 | AY17: 0 | AZ17: 0 | BA17: 0 | BB17: 0 | BC17: 0 | BD17: 0 | BE17: 0 | BF17: 0 | BG17: 0 | BH17: 0 | BI17: 0 | BJ17: 0 | BK17: 0 | BL17: 0 | BM17: 0 | BN17: 0 | BO17: =G17-H17+I17-J17+K17-L17+M17-N17+O17-P17+Q17-R17+S17-T17+U17-V17+W17-X17+Y17-Z17+AA17-AB17+AC17-AD17+AE17-AF17+AG17-AH17+AI17-AJ17+AK17-AL17+AM17-AN17+AO17-AP17+AQ17-AR17+AS17-AT17+AU17-AV17+AW17-AX17+AY17-AZ17+BA17-+BB17+BC17-BD17+BE17-BF17+BG17-BH17+BI17-BJ17+BK17-BL17+BM17-BN17 -> 0 | BP17: 0 | BQ17: =C17*BP17 -> 0 | BR17: =D17*BP17 -> 0 | BS17: =E17*BP17 -> 0
A18: Malta | B18: ea | C18: =SUM(G18+I18+K18+M18+O18+Q18+S18+U18+W18+Y18+AA18+AC18+AE18+AG18+AI18+AK18+AM18+AO18+AQ18+AS18+AU18+AW18+AY18+BA18+BC18+BE18+BG18+BI18+BK18+BM18) -> 3600 | D18: =H18+J18+L18+N18+P18+R18+T18+V18+X18+Z18+AB18+AD18+AF18+AH18+AJ18+AL18+AN18+AP18+AR18+AT18+AV18+AX18+AZ18+BB18+BD18+BF18+BH18+BJ18+BL18+BN18 -> 0 | E18: =C18-D18 -> 3600 | F18: MG | G18: 0 | H18: 0 | I18: 0 | J18: 0 | K18: 0 | L18: 0 | M18: 0 | N18: 0 | O18: 0 | P18: 0 | Q18: 0 | R18: 0 | S18: 0 | T18: 0 | U18: 0 | V18: 0 | W18: 0 | X18: 0 | Y18: 0 | Z18: 0 | AA18: 0 | AB18: 0 | AC18: 0 | AD18: 0 | AE18: 3600 | AF18: 0 | AG18: 0 | AH18: 0 | AI18: 0 | AJ18: 0 | AK18: 0 | AL18: 0 | AM18: 0 | AN18: 0 | AO18: 0 | AP18: 0 | AQ18: 0 | AR18: 0 | AS18: 0 | AT18: 0 | AU18: 0 | AV18: 0 | AW18: 0 | AX18: 0 | AY18: 0 | AZ18: 0 | BA18: 0 | BB18: 0 | BC18: 0 | BD18: 0 | BE18: 0 | BF18: 0 | BG18: 0 | BH18: 0 | BI18: 0 | BJ18: 0 | BK18: 0 | BL18: 0 | BM18: 0 | BN18: 0 | BO18: =G18-H18+I18-J18+K18-L18+M18-N18+O18-P18+Q18-R18+S18-T18+U18-V18+W18-X18+Y18-Z18+AA18-AB18+AC18-AD18+AE18-AF18+AG18-AH18+AI18-AJ18+AK18-AL18+AM18-AN18+AO18-AP18+AQ18-AR18+AS18-AT18+AU18-AV18+AW18-AX18+AY18-AZ18+BA18-+BB18+BC18-BD18+BE18-BF18+BG18-BH18+BI18-BJ18+BK18-BL18+BM18-BN18 -> 3600 | BP18: 0 | BQ18: =C18*BP18 -> 0 | BR18: =D18*BP18 -> 0 | BS18: =E18*BP18 -> 0
A19: Rice | B19: ea | C19: =SUM(G19+I19+K19+M19+O19+Q19+S19+U19+W19+Y19+AA19+AC19+AE19+AG19+AI19+AK19+AM19+AO19+AQ19+AS19+AU19+AW19+AY19+BA19+BC19+BE19+BG19+BI19+BK19+BM19) -> 2940 | D19: =H19+J19+L19+N19+P19+R19+T19+V19+X19+Z19+AB19+AD19+AF19+AH19+AJ19+AL19+AN19+AP19+AR19+AT19+AV19+AX19+AZ19+BB19+BD19+BF19+BH19+BJ19+BL19+BN19 -> 0 | E19: =C19-D19 -> 2940 | F19: KW | G19: 0 | H19: 0 | I19: 0 | J19: 0 | K19: 0 | L19: 0 | M19: 0 | N19: 0 | O19: 0 | P19: 0 | Q19: 0 | R19: 0 | S19: 0 | T19: 0 | U19: 0 | V19: 0 | W19: 0 | X19: 0 | Y19: 0 | Z19: 0 | AA19: 0 | AB19: 0 | AC19: 0 | AD19: 0 | AE19: 0 | AF19: 0 | AG19: 0 | AH19: 0 | AI19: 2940 | AJ19: 0 | AK19: 0 | AL19: 0 | AM19: 0 | AN19: 0 | AO19: 0 | AP19: 0 | AQ19: 0 | AR19: 0 | AS19: 0 | AT19: 0 | AU19: 0 | AV19: 0 | AW19: 0 | AX19: 0 | AY19: 0 | AZ19: 0 | BA19: 0 | BB19: 0 | BC19: 0 | BD19: 0 | BE19: 0 | BF19: 0 | BG19: 0 | BH19: 0 | BI19: 0 | BJ19: 0 | BK19: 0 | BL19: 0 | BM19: 0 | BN19: 0 | BO19: =G19-H19+I19-J19+K19-L19+M19-N19+O19-P19+Q19-R19+S19-T19+U19-V19+W19-X19+Y19-Z19+AA19-AB19+AC19-AD19+AE19-AF19+AG19-AH19+AI19-AJ19+AK19-AL19+AM19-AN19+AO19-AP19+AQ19-AR19+AS19-AT19+AU19-AV19+AW19-AX19+AY19-AZ19+BA19-+BB19+BC19-BD19+BE19-BF19+BG19-BH19+BI19-BJ19+BK19-BL19+BM19-BN19 -> 2940 | BP19: 0 | BQ19: =C19*BP19 -> 0 | BR19: =D19*BP19 -> 0 | BS19: =E19*BP19 -> 0
A20: Sugar | B20: ea | C20: =SUM(G20+I20+K20+M20+O20+Q20+S20+U20+W20+Y20+AA20+AC20+AE20+AG20+AI20+AK20+AM20+AO20+AQ20+AS20+AU20+AW20+AY20+BA20+BC20+BE20+BG20+BI20+BK20+BM20) -> 4776 | D20: =H20+J20+L20+N20+P20+R20+T20+V20+X20+Z20+AB20+AD20+AF20+AH20+AJ20+AL20+AN20+AP20+AR20+AT20+AV20+AX20+AZ20+BB20+BD20+BF20+BH20+BJ20+BL20+BN20 -> 0 | E20: =C20-D20 -> 4776 | F20: KW | G20: 0 | H20: 0 | I20: 0 | J20: 0 | K20: 0 | L20: 0 | M20: 0 | N20: 0 | O20: 0 | P20: 0 | Q20: 0 | R20: 0 | S20: 0 | T20: 0 | U20: 0 | V20: 0 | W20: 0 | X20: 0 | Y20: 0 | Z20: 0 | AA20: 0 | AB20: 0 | AC20: 0 | AD20: 0 | AE20: 0 | AF20: 0 | AG20: 0 | AH20: 0 | AI20: =4776 -> 4776 | AJ20: 0 | AK20: 0 | AL20: 0 | AM20: 0 | AN20: 0 | AO20: 0 | AP20: 0 | AQ20: 0 | AR20: 0 | AS20: 0 | AT20: 0 | AU20: 0 | AV20: 0 | AW20: 0 | AX20: 0 | AY20: 0 | AZ20: 0 | BA20: 0 | BB20: 0 | BC20: 0 | BD20: 0 | BE20: 0 | BF20: 0 | BG20: 0 | BH20: 0 | BI20: 0 | BJ20: 0 | BK20: 0 | BL20: 0 | BM20: 0 | BN20: 0 | BO20: =G20-H20+I20-J20+K20-L20+M20-N20+O20-P20+Q20-R20+S20-T20+U20-V20+W20-X20+Y20-Z20+AA20-AB20+AC20-AD20+AE20-AF20+AG20-AH20+AI20-AJ20+AK20-AL20+AM20-AN20+AO20-AP20+AQ20-AR20+AS20-AT20+AU20-AV20+AW20-AX20+AY20-AZ20+BA20-+BB20+BC20-BD20+BE20-BF20+BG20-BH20+BI20-BJ20+BK20-BL20+BM20-BN20 -> 4776 | BP20: 0 | BQ20: =C20*BP20 -> 0 | BR20: =D20*BP20 -> 0 | BS20: =E20*BP20 -> 0
A21: Tuna | B21: ea | C21: =SUM(G21+I21+K21+M21+O21+Q21+S21+U21+W21+Y21+AA21+AC21+AE21+AG21+AI21+AK21+AM21+AO21+AQ21+AS21+AU21+AW21+AY21+BA21+BC21+BE21+BG21+BI21+BK21+BM21) -> 30336 | D21: =H21+J21+L21+N21+P21+R21+T21+V21+X21+Z21+AB21+AD21+AF21+AH21+AJ21+AL21+AN21+AP21+AR21+AT21+AV21+AX21+AZ21+BB21+BD21+BF21+BH21+BJ21+BL21+BN21 -> 0 | E21: =C21-D21 -> 30336 | F21: KW | G21: 0 | H21: 0 | I21: 0 | J21: 0 | K21: 0 | L21: 0 | M21: 0 | N21: 0 | O21: 0 | P21: 0 | Q21: 0 | R21: 0 | S21: 0 | T21: 0 | U21: 0 | V21: 0 | W21: 0 | X21: 0 | Y21: 0 | Z21: 0 | AA21: 0 | AB21: 0 | AC21: 0 | AD21: 0 | AE21: 0 | AF21: 0 | AG21: 0 | AH21: 0 | AI21: =15600+4848+8448+1440 -> 30336 | AJ21: 0 | AK21: 0 | AL21: 0 | AM21: 0 | AN21: 0 | AO21: 0 | AP21: 0 | AQ21: 0 | AR21: 0 | AS21: 0 | AT21: 0 | AU21: 0 | AV21: 0 | AW21: 0 | AX21: 0 | AY21: 0 | AZ21: 0 | BA21: 0 | BB21: 0 | BC21: 0 | BD21: 0 | BE21: 0 | BF21: 0 | BG21: 0 | BH21: 0 | BI21: 0 | BJ21: 0 | BK21: 0 | BL21: 0 | BM21: 0 | BN21: 0 | BO21: =G21-H21+I21-J21+K21-L21+M21-N21+O21-P21+Q21-R21+S21-T21+U21-V21+W21-X21+Y21-Z21+AA21-AB21+AC21-AD21+AE21-AF21+AG21-AH21+AI21-AJ21+AK21-AL21+AM21-AN21+AO21-AP21+AQ21-AR21+AS21-AT21+AU21-AV21+AW21-AX21+AY21-AZ21+BA21-+BB21+BC21-BD21+BE21-BF21+BG21-BH21+BI21-BJ21+BK21-BL21+BM21-BN21 -> 30336 | BP21: 0 | BQ21: =C21*BP21 -> 0 | BR21: =D21*BP21 -> 0 | BS21: =E21*BP21 -> 0
A22: Pigeon Peas | B22: ea | C22: =SUM(G22+I22+K22+M22+O22+Q22+S22+U22+W22+Y22+AA22+AC22+AE22+AG22+AI22+AK22+AM22+AO22+AQ22+AS22+AU22+AW22+AY22+BA22+BC22+BE22+BG22+BI22+BK22+BM22) -> 480 | D22: =H22+J22+L22+N22+P22+R22+T22+V22+X22+Z22+AB22+AD22+AF22+AH22+AJ22+AL22+AN22+AP22+AR22+AT22+AV22+AX22+AZ22+BB22+BD22+BF22+BH22+BJ22+BL22+BN22 -> 0 | E22: =C22-D22 -> 480 | F22: KW | G22: 0 | H22: 0 | I22: 0 | J22: 0 | K22: 0 | L22: 0 | M22: 0 | N22: 0 | O22: 0 | P22: 0 | Q22: 0 | R22: 0 | S22: 0 | T22: 0 | U22: 0 | V22: 0 | W22: 0 | X22: 0 | Y22: 0 | Z22: 0 | AA22: 0 | AB22: 0 | AC22: 0 | AD22: 0 | AE22: 0 | AF22: 0 | AG22: 0 | AH22: 0 | AI22: 480 | AJ22: 0 | AK22: 0 | AL22: 0 | AM22: 0 | AN22: 0 | AO22: 0 | AP22: 0 | AQ22: 0 | AR22: 0 | AS22: 0 | AT22: 0 | AU22: 0 | AV22: 0 | AW22: 0 | AX22: 0 | AY22: 0 | AZ22: 0 | BA22: 0 | BB22: 0 | BC22: 0 | BD22: 0 | BE22: 0 | BF22: 0 | BG22: 0 | BH22: 0 | BI22: 0 | BJ22: 0 | BK22: 0 | BL22: 0 | BM22: 0 | BN22: 0 | BO22: =G22-H22+I22-J22+K22-L22+M22-N22+O22-P22+Q22-R22+S22-T22+U22-V22+W22-X22+Y22-Z22+AA22-AB22+AC22-AD22+AE22-AF22+AG22-AH22+AI22-AJ22+AK22-AL22+AM22-AN22+AO22-AP22+AQ22-AR22+AS22-AT22+AU22-AV22+AW22-AX22+AY22-AZ22+BA22-+BB22+BC22-BD22+BE22-BF22+BG22-BH22+BI22-BJ22+BK22-BL22+BM22-BN22 -> 480 | BP22: 0 | BQ22: =C22*BP22 -> 0 | BR22: =D22*BP22 -> 0 | BS22: =E22*BP22 -> 0
A23: Bag Noodles (Ramen) | B23: ea | C23: =SUM(G23+I23+K23+M23+O23+Q23+S23+U23+W23+Y23+AA23+AC23+AE23+AG23+AI23+AK23+AM23+AO23+AQ23+AS23+AU23+AW23+AY23+BA23+BC23+BE23+BG23+BI23+BK23+BM23) -> 12288 | D23: =H23+J23+L23+N23+P23+R23+T23+V23+X23+Z23+AB23+AD23+AF23+AH23+AJ23+AL23+AN23+AP23+AR23+AT23+AV23+AX23+AZ23+BB23+BD23+BF23+BH23+BJ23+BL23+BN23 -> 0 | E23: =C23-D23 -> 12288 | F23: KW | G23: 0 | H23: 0 | I23: 0 | J23: 0 | K23: 0 | L23: 0 | M23: 0 | N23: 0 | O23: 0 | P23: 0 | Q23: 0 | R23: 0 | S23: 0 | T23: 0 | U23: 0 | V23: 0 | W23: 0 | X23: 0 | Y23: 0 | Z23: 0 | AA23: 0 | AB23: 0 | AC23: 0 | AD23: 0 | AE23: 0 | AF23: 0 | AG23: 0 | AH23: 0 | AI23: 12288 | AJ23: 0 | AK23: 0 | AL23: 0 | AM23: 0 | AN23: 0 | AO23: 0 | AP23: 0 | AQ23: 0 | AR23: 0 | AS23: 0 | AT23: 0 | AU23: 0 | AV23: 0 | AW23: 0 | AX23: 0 | AY23: 0 | AZ23: 0 | BA23: 0 | BB23: 0 | BC23: 0 | BD23: 0 | BE23: 0 | BF23: 0 | BG23: 0 | BH23: 0 | BI23: 0 | BJ23: 0 | BK23: 0 | BL23: 0 | BM23: 0 | BN23: 0 | BO23: =G23-H23+I23-J23+K23-L23+M23-N23+O23-P23+Q23-R23+S23-T23+U23-V23+W23-X23+Y23-Z23+AA23-AB23+AC23-AD23+AE23-AF23+AG23-AH23+AI23-AJ23+AK23-AL23+AM23-AN23+AO23-AP23+AQ23-AR23+AS23-AT23+AU23-AV23+AW23-AX23+AY23-AZ23+BA23-+BB23+BC23-BD23+BE23-BF23+BG23-BH23+BI23-BJ23+BK23-BL23+BM23-BN23 -> 12288 | BP23: 0 | BQ23: =C23*BP23 -> 0 | BR23: =D23*BP23 -> 0 | BS23: =E23*BP23 -> 0
A24: Mix Vegetables | B24: ea | C24: =SUM(G24+I24+K24+M24+O24+Q24+S24+U24+W24+Y24+AA24+AC24+AE24+AG24+AI24+AK24+AM24+AO24+AQ24+AS24+AU24+AW24+AY24+BA24+BC24+BE24+BG24+BI24+BK24+BM24) -> 672 | D24: =H24+J24+L24+N24+P24+R24+T24+V24+X24+Z24+AB24+AD24+AF24+AH24+AJ24+AL24+AN24+AP24+AR24+AT24+AV24+AX24+AZ24+BB24+BD24+BF24+BH24+BJ24+BL24+BN24 -> 0 | E24: =C24-D24 -> 672 | F24: KW | G24: 0 | H24: 0 | I24: 0 | J24: 0 | K24: 0 | L24: 0 | M24: 0 | N24: 0 | O24: 0 | P24: 0 | Q24: 0 | R24: 0 | S24: 0 | T24: 0 | U24: 0 | V24: 0 | W24: 0 | X24: 0 | Y24: 0 | Z24: 0 | AA24: 0 | AB24: 0 | AC24: 0 | AD24: 0 | AE24: 0 | AF24: 0 | AG24: 0 | AH24: 0 | AI24: 672 | AJ24: 0 | AK24: 0 | AL24: 0 | AM24: 0 | AN24: 0 | AO24: 0 | AP24: 0 | AQ24: 0 | AR24: 0 | AS24: 0 | AT24: 0 | AU24: 0 | AV24: 0 | AW24: 0 | AX24: 0 | AY24: 0 | AZ24: 0 | BA24: 0 | BB24: 0 | BC24: 0 | BD24: 0 | BE24: 0 | BF24: 0 | BG24: 0 | BH24: 0 | BI24: 0 | BJ24: 0 | BK24: 0 | BL24: 0 | BM24: 0 | BN24: 0 | BO24: =G24-H24+I24-J24+K24-L24+M24-N24+O24-P24+Q24-R24+S24-T24+U24-V24+W24-X24+Y24-Z24+AA24-AB24+AC24-AD24+AE24-AF24+AG24-AH24+AI24-AJ24+AK24-AL24+AM24-AN24+AO24-AP24+AQ24-AR24+AS24-AT24+AU24-AV24+AW24-AX24+AY24-AZ24+BA24-+BB24+BC24-BD24+BE24-BF24+BG24-BH24+BI24-BJ24+BK24-BL24+BM24-BN24 -> 672 | BP24: 0 | BQ24: =C24*BP24 -> 0 | BR24: =D24*BP24 -> 0 | BS24: =E24*BP24 -> 0
A25: Cornbeef | B25: ea | C25: =SUM(G25+I25+K25+M25+O25+Q25+S25+U25+W25+Y25+AA25+AC25+AE25+AG25+AI25+AK25+AM25+AO25+AQ25+AS25+AU25+AW25+AY25+BA25+BC25+BE25+BG25+BI25+BK25+BM25) -> 9120 | D25: =H25+J25+L25+N25+P25+R25+T25+V25+X25+Z25+AB25+AD25+AF25+AH25+AJ25+AL25+AN25+AP25+AR25+AT25+AV25+AX25+AZ25+BB25+BD25+BF25+BH25+BJ25+BL25+BN25 -> 0 | E25: =C25-D25 -> 9120 | F25: KW | G25: 0 | H25: 0 | I25: 0 | J25: 0 | K25: 0 | L25: 0 | M25: 0 | N25: 0 | O25: 0 | P25: 0 | Q25: 0 | R25: 0 | S25: 0 | T25: 0 | U25: 0 | V25: 0 | W25: 0 | X25: 0 | Y25: 0 | Z25: 0 | AA25: 0 | AB25: 0 | AC25: 0 | AD25: 0 | AE25: 0 | AF25: 0 | AG25: 0 | AH25: 0 | AI25: =2496+6624 -> 9120 | AJ25: 0 | AK25: 0 | AL25: 0 | AM25: 0 | AN25: 0 | AO25: 0 | AP25: 0 | AQ25: 0 | AR25: 0 | AS25: 0 | AT25: 0 | AU25: 0 | AV25: 0 | AW25: 0 | AX25: 0 | AY25: 0 | AZ25: 0 | BA25: 0 | BB25: 0 | BC25: 0 | BD25: 0 | BE25: 0 | BF25: 0 | BG25: 0 | BH25: 0 | BI25: 0 | BJ25: 0 | BK25: 0 | BL25: 0 | BM25: 0 | BN25: 0 | BO25: =G25-H25+I25-J25+K25-L25+M25-N25+O25-P25+Q25-R25+S25-T25+U25-V25+W25-X25+Y25-Z25+AA25-AB25+AC25-AD25+AE25-AF25+AG25-AH25+AI25-AJ25+AK25-AL25+AM25-AN25+AO25-AP25+AQ25-AR25+AS25-AT25+AU25-AV25+AW25-AX25+AY25-AZ25+BA25-+BB25+BC25-BD25+BE25-BF25+BG25-BH25+BI25-BJ25+BK25-BL25+BM25-BN25 -> 9120 | BP25: 0 | BQ25: =C25*BP25 -> 0 | BR25: =D25*BP25 -> 0 | BS25: =E25*BP25 -> 0

Sheet Medical Supplies 
A1: Description of Items | B1: Unit | C1: Total Quantity Received | D1: Total Quantity Issued | E1: Quantity in store | F1: Location | G1: 45960 | I1: 45961 | K1: 45962 | M1: 45963 | O1: 45964 | Q1: 45965 | S1: 45966 | U1: 45967 | W1: 45968 | Y1: 45969 | AA1: 45970 | AC1: 45971 | AE1: 45972 | AG1: 45973 | AI1: 45974 | AK1: 45975 | AM1: 45976 | AO1: 45977 | AQ1: 45978 | AS1: 45979 | AU1: 45980 | AW1: 45981 | AY1: 45982 | BA1: 45983 | BC1: 45984 | BE1: 45985 | BG1: 45986 | BI1: 45987 | BK1: 45988 | BM1: 45989 | BO1: Quantity in Store | BP1: Unit Cost | BQ1: Total Cost | BR1: Issued (USD) | BS1: Balance (USD)
G2: Received | H2: Issue | I2: Received | J2: Issue | K2: Received | L2: Issue | M2: Received | N2: Issue | O2: Received | P2: Issue | Q2: Received | R2: Issue | S2: Received | T2: Issue | U2: Received | V2: Issue | W2: Received | X2: Issue | Y2: Received | Z2: Issue | AA2: Received | AB2: Issue | AC2: Received | AD2: Issue | AE2: Received | AF2: Issue | AG2: Received | AH2: Issue | AI2: Received | AJ2: Issue | AK2: Received | AL2: Issue | AM2: Received | AN2: Issue | AO2: Received | AP2: Issue | AQ2: Received | AR2: Issue | AS2: Received | AT2: Issue | AU2: Received | AV2: Issue | AW2: Received | AX2: Issue | AY2: Received | AZ2: Issue | BA2: Received | BB2: Issue | BC2: Received | BD2: Issue | BE2: Received | BF2: Issue | BG2: Received | BH2: Issue | BI2: Received | BJ2: Issue | BK2: Received | BL2: Issue | BM2: Received | BN2: Issue
A3: First Aid Kit | B3: ea | C3: =SUM(G3+I3+K3+M3+O3+Q3+S3+U3+W3+Y3+AA3+AC3+AE3+AG3+AI3+AK3+AM3+AO3+AQ3+AS3+AU3+AW3+AY3+BA3+BC3+BE3+BG3+BI3+BK3+BM3) -> 88 | D3: =SUM(H3+J3+L3+N3+P3+R3+T3+V3+X3+Z3+AB3+AD3+AF3+AJ3+AH3+AL3+AN3+AP3+AR3+AT3+AV3+AX3+AZ3+BB3+BD3+BF3+BH3+BJ3+BL3+BN3) -> 88 | E3: =C3-D3 -> 0 | G3: 88 | H3: 0 | I3: 0 | J3: 0 | K3: =I3-J3 -> 0 | L3: 0 | M3: =K3-L3 -> 0 | N3: 0 | O3: =M3-N3 -> 0 | P3: 88 | Q3: 0 | R3: 0 | S3: 0 | T3: 0 | U3: 0 | V3: 0 | W3: 0 | X3: 0 | Y3: 0 | Z3: 0 | AA3: 0 | AB3: 0 | AC3: 0 | AD3: 0 | AE3: 0 | AF3: 0 | AG3: 0 | AH3: 0 | AI3: 0 | AJ3: 0 | AK3: 0 | AL3: 0 | AM3: 0 | AN3: 0 | AO3: 0 | AP3: 0 | AQ3: 0 | AR3: 0 | AS3: 0 | AT3: 0 | AU3: 0 | AV3: 0 | AW3: 0 | AX3: 0 | AY3: 0 | AZ3: 0 | BA3: 0 | BB3: 0 | BC3: 0 | BD3: 0 | BE3: 0 | BF3: 0 | BG3: 0 | BH3: 0 | BI3: 0 | BJ3: 0 | BK3: 0 | BL3: 0 | BM3: 0 | BN3: 0 | BO3: =G3-H3+I3-J3+K3-L3+M3-N3+O3-P3+Q3-R3+S3-T3+U3-V3+W3-X3+Y3-Z3+AA3-AB3+AC3-AD3+AE3-AF3+AG3-AH3+AI3-AJ3+AK3-AL3+AM3-AN3+AO3-AP3+AQ3-AR3+AS3-AT3+AU3-AV3+AW3-AX3+AY3-AZ3+BA3-BB3+BC3-BD3+BE3-BF3+BG3-BH3+BI3-BJ3+BK3-BL3+BM3-BN3 -> 0 | BP3: 15 | BQ3: =C3*BP3 -> 1320 | BR3: =D3*BP3 -> 1320 | BS3: =E3*BP3 -> 0
A4: Surgeon Caps | B4: ea | C4: =SUM(G4+I4+K4+M4+O4+Q4+S4+U4+W4+Y4+AA4+AC4+AE4+AG4+AI4+AK4+AM4+AO4+AQ4+AS4+AU4+AW4+AY4+BA4+BC4+BE4+BG4+BI4+BK4+BM4) -> 5000 | D4: =SUM(H4+J4+L4+N4+P4+R4+T4+V4+X4+Z4+AB4+AD4+AF4+AJ4+AH4+AL4+AN4+AP4+AR4+AT4+AV4+AX4+AZ4+BB4+BD4+BF4+BH4+BJ4+BL4+BN4) -> 5000 | E4: =C4-D4 -> 0 | G4: 5000 | H4: 0 | I4: 0 | J4: 0 | K4: =I4-J4 -> 0 | L4: 0 | M4: =K4-L4 -> 0 | N4: 0 | O4: =M4-N4 -> 0 | P4: 5000 | Q4: 0 | R4: 0 | S4: 0 | T4: 0 | U4: 0 | V4: 0 | W4: 0 | X4: 0 | Y4: 0 | Z4: 0 | AA4: 0 | AB4: 0 | AC4: 0 | AD4: 0 | AE4: 0 | AF4: 0 | AG4: 0 | AH4: 0 | AI4: 0 | AJ4: 0 | AK4: 0 | AL4: 0 | AM4: 0 | AN4: 0 | AO4: 0 | AP4: 0 | AQ4: 0 | AR4: 0 | AS4: 0 | AT4: 0 | AU4: 0 | AV4: 0 | AW4: 0 | AX4: 0 | AY4: 0 | AZ4: 0 | BA4: 0 | BB4: 0 | BC4: 0 | BD4: 0 | BE4: 0 | BF4: 0 | BG4: 0 | BH4: 0 | BI4: 0 | BJ4: 0 | BK4: 0 | BL4: 0 | BM4: 0 | BN4: 0 | BO4: =G4-H4+I4-J4+K4-L4+M4-N4+O4-P4+Q4-R4+S4-T4+U4-V4+W4-X4+Y4-Z4+AA4-AB4+AC4-AD4+AE4-AF4+AG4-AH4+AI4-AJ4+AK4-AL4+AM4-AN4+AO4-AP4+AQ4-AR4+AS4-AT4+AU4-AV4+AW4-AX4+AY4-AZ4+BA4-BB4+BC4-BD4+BE4-BF4+BG4-BH4+BI4-BJ4+BK4-BL4+BM4-BN4 -> 0 | BP4: 0.02 | BQ4: =C4*BP4 -> 100 | BR4: =D4*BP4 -> 100 | BS4: =E4*BP4 -> 0
A5: Vanish Point Syringe | B5: ea | C5: =SUM(G5+I5+K5+M5+O5+Q5+S5+U5+W5+Y5+AA5+AC5+AE5+AG5+AI5+AK5+AM5+AO5+AQ5+AS5+AU5+AW5+AY5+BA5+BC5+BE5+BG5+BI5+BK5+BM5) -> 300 | D5: =SUM(H5+J5+L5+N5+P5+R5+T5+V5+X5+Z5+AB5+AD5+AF5+AJ5+AH5+AL5+AN5+AP5+AR5+AT5+AV5+AX5+AZ5+BB5+BD5+BF5+BH5+BJ5+BL5+BN5) -> 300 | E5: =C5-D5 -> 0 | G5: 300 | H5: 0 | I5: 0 | J5: 0 | K5: =I5-J5 -> 0 | L5: 0 | M5: =K5-L5 -> 0 | N5: 0 | O5: =M5-N5 -> 0 | P5: 300 | Q5: 0 | R5: 0 | S5: 0 | T5: 0 | U5: 0 | V5: 0 | W5: 0 | X5: 0 | Y5: 0 | Z5: 0 | AA5: 0 | AB5: 0 | AC5: 0 | AD5: 0 | AE5: 0 | AF5: 0 | AG5: 0 | AH5: 0 | AI5: 0 | AJ5: 0 | AK5: 0 | AL5: 0 | AM5: 0 | AN5: 0 | AO5: 0 | AP5: 0 | AQ5: 0 | AR5: 0 | AS5: 0 | AT5: 0 | AU5: 0 | AV5: 0 | AW5: 0 | AX5: 0 | AY5: 0 | AZ5: 0 | BA5: 0 | BB5: 0 | BC5: 0 | BD5: 0 | BE5: 0 | BF5: 0 | BG5: 0 | BH5: 0 | BI5: 0 | BJ5: 0 | BK5: 0 | BL5: 0 | BM5: 0 | BN5: 0 | BO5: =G5-H5+I5-J5+K5-L5+M5-N5+O5-P5+Q5-R5+S5-T5+U5-V5+W5-X5+Y5-Z5+AA5-AB5+AC5-AD5+AE5-AF5+AG5-AH5+AI5-AJ5+AK5-AL5+AM5-AN5+AO5-AP5+AQ5-AR5+AS5-AT5+AU5-AV5+AW5-AX5+AY5-AZ5+BA5-BB5+BC5-BD5+BE5-BF5+BG5-BH5+BI5-BJ5+BK5-BL5+BM5-BN5 -> 0 | BP5: 2 | BQ5: =C5*BP5 -> 600 | BR5: =D5*BP5 -> 600 | BS5: =E5*BP5 -> 0
A6: N95 Masks | B6: ea | C6: =SUM(G6+I6+K6+M6+O6+Q6+S6+U6+W6+Y6+AA6+AC6+AE6+AG6+AI6+AK6+AM6+AO6+AQ6+AS6+AU6+AW6+AY6+BA6+BC6+BE6+BG6+BI6+BK6+BM6) -> 4478 | D6: =SUM(H6+J6+L6+N6+P6+R6+T6+V6+X6+Z6+AB6+AD6+AF6+AJ6+AH6+AL6+AN6+AP6+AR6+AT6+AV6+AX6+AZ6+BB6+BD6+BF6+BH6+BJ6+BL6+BN6) -> 3228 | E6: =C6-D6 -> 1250 | F6: MG | G6: 3228 | H6: 0 | I6: 0 | J6: 0 | K6: 500 | L6: 0 | M6: 0 | N6: 0 | O6: 0 | P6: 3228 | Q6: 0 | R6: 0 | S6: 0 | T6: 0 | U6: 750 | V6: 0 | W6: 0 | X6: 0 | Y6: 0 | Z6: 0 | AA6: 0 | AB6: 0 | AC6: 0 | AD6: 0 | AE6: 0 | AF6: 0 | AG6: 0 | AH6: 0 | AI6: 0 | AJ6: 0 | AK6: 0 | AL6: 0 | AM6: 0 | AN6: 0 | AO6: 0 | AP6: 0 | AQ6: 0 | AR6: 0 | AS6: 0 | AT6: 0 | AU6: 0 | AV6: 0 | AW6: 0 | AX6: 0 | AY6: 0 | AZ6: 0 | BA6: 0 | BB6: 0 | BC6: 0 | BD6: 0 | BE6: 0 | BF6: 0 | BG6: 0 | BH6: 0 | BI6: 0 | BJ6: 0 | BK6: 0 | BL6: 0 | BM6: 0 | BN6: 0 | BO6: =G6-H6+I6-J6+K6-L6+M6-N6+O6-P6+Q6-R6+S6-T6+U6-V6+W6-X6+Y6-Z6+AA6-AB6+AC6-AD6+AE6-AF6+AG6-AH6+AI6-AJ6+AK6-AL6+AM6-AN6+AO6-AP6+AQ6-AR6+AS6-AT6+AU6-AV6+AW6-AX6+AY6-AZ6+BA6-BB6+BC6-BD6+BE6-BF6+BG6-BH6+BI6-BJ6+BK6-BL6+BM6-BN6 -> 1250 | BP6: 0.02 | BQ6: =C6*BP6 -> 89.56 | BR6: =D6*BP6 -> 64.56 | BS6: =E6*BP6 -> 25
A7: Surgical Gowns | B7: ea | C7: =SUM(G7+I7+K7+M7+O7+Q7+S7+U7+W7+Y7+AA7+AC7+AE7+AG7+AI7+AK7+AM7+AO7+AQ7+AS7+AU7+AW7+AY7+BA7+BC7+BE7+BG7+BI7+BK7+BM7) -> 1550 | D7: =SUM(H7+J7+L7+N7+P7+R7+T7+V7+X7+Z7+AB7+AD7+AF7+AJ7+AH7+AL7+AN7+AP7+AR7+AT7+AV7+AX7+AZ7+BB7+BD7+BF7+BH7+BJ7+BL7+BN7) -> 1550 | E7: =C7-D7 -> 0 | G7: 1550 | H7: 0 | I7: 0 | J7: 0 | K7: =I7-J7 -> 0 | L7: 0 | M7: =K7-L7 -> 0 | N7: 0 | O7: =M7-N7 -> 0 | P7: 1550 | Q7: 0 | R7: 0 | S7: 0 | T7: 0 | U7: 0 | V7: 0 | W7: 0 | X7: 0 | Y7: 0 | Z7: 0 | AA7: 0 | AB7: 0 | AC7: 0 | AD7: 0 | AE7: 0 | AF7: 0 | AG7: 0 | AH7: 0 | AI7: 0 | AJ7: 0 | AK7: 0 | AL7: 0 | AM7: 0 | AN7: 0 | AO7: 0 | AP7: 0 | AQ7: 0 | AR7: 0 | AS7: 0 | AT7: 0 | AU7: 0 | AV7: 0 | AW7: 0 | AX7: 0 | AY7: 0 | AZ7: 0 | BA7: 0 | BB7: 0 | BC7: 0 | BD7: 0 | BE7: 0 | BF7: 0 | BG7: 0 | BH7: 0 | BI7: 0 | BJ7: 0 | BK7: 0 | BL7: 0 | BM7: 0 | BN7: 0 | BO7: =G7-H7+I7-J7+K7-L7+M7-N7+O7-P7+Q7-R7+S7-T7+U7-V7+W7-X7+Y7-Z7+AA7-AB7+AC7-AD7+AE7-AF7+AG7-AH7+AI7-AJ7+AK7-AL7+AM7-AN7+AO7-AP7+AQ7-AR7+AS7-AT7+AU7-AV7+AW7-AX7+AY7-AZ7+BA7-BB7+BC7-BD7+BE7-BF7+BG7-BH7+BI7-BJ7+BK7-BL7+BM7-BN7 -> 0 | BP7: 0.05 | BQ7: =C7*BP7 -> 77.5 | BR7: =D7*BP7 -> 77.5 | BS7: =E7*BP7 -> 0
A8: Specimen Containers | B8: ea | C8: =SUM(G8+I8+K8+M8+O8+Q8+S8+U8+W8+Y8+AA8+AC8+AE8+AG8+AI8+AK8+AM8+AO8+AQ8+AS8+AU8+AW8+AY8+BA8+BC8+BE8+BG8+BI8+BK8+BM8) -> 4800 | D8: =SUM(H8+J8+L8+N8+P8+R8+T8+V8+X8+Z8+AB8+AD8+AF8+AJ8+AH8+AL8+AN8+AP8+AR8+AT8+AV8+AX8+AZ8+BB8+BD8+BF8+BH8+BJ8+BL8+BN8) -> 4800 | E8: =C8-D8 -> 0 | G8: 4800 | H8: 0 | I8: 0 | J8: 0 | K8: =I8-J8 -> 0 | L8: 0 | M8: =K8-L8 -> 0 | N8: 0 | O8: =M8-N8 -> 0 | P8: 4800 | Q8: 0 | R8: 0 | S8: 0 | T8: 0 | U8: 0 | V8: 0 | W8: 0 | X8: 0 | Y8: 0 | Z8: 0 | AA8: 0 | AB8: 0 | AC8: 0 | AD8: 0 | AE8: 0 | AF8: 0 | AG8: 0 | AH8: 0 | AI8: 0 | AJ8: 0 | AK8: 0 | AL8: 0 | AM8: 0 | AN8: 0 | AO8: 0 | AP8: 0 | AQ8: 0 | AR8: 0 | AS8: 0 | AT8: 0 | AU8: 0 | AV8: 0 | AW8: 0 | AX8: 0 | AY8: 0 | AZ8: 0 | BA8: 0 | BB8: 0 | BC8: 0 | BD8: 0 | BE8: 0 | BF8: 0 | BG8: 0 | BH8: 0 | BI8: 0 | BJ8: 0 | BK8: 0 | BL8: 0 | BM8: 0 | BN8: 0 | BO8: =G8-H8+I8-J8+K8-L8+M8-N8+O8-P8+Q8-R8+S8-T8+U8-V8+W8-X8+Y8-Z8+AA8-AB8+AC8-AD8+AE8-AF8+AG8-AH8+AI8-AJ8+AK8-AL8+AM8-AN8+AO8-AP8+AQ8-AR8+AS8-AT8+AU8-AV8+AW8-AX8+AY8-AZ8+BA8-BB8+BC8-BD8+BE8-BF8+BG8-BH8+BI8-BJ8+BK8-BL8+BM8-BN8 -> 0 | BP8: 0.5 | BQ8: =C8*BP8 -> 2400 | BR8: =D8*BP8 -> 2400 | BS8: =E8*BP8 -> 0
A9: Insulin Syringes | B9: ea | C9: =SUM(G9+I9+K9+M9+O9+Q9+S9+U9+W9+Y9+AA9+AC9+AE9+AG9+AI9+AK9+AM9+AO9+AQ9+AS9+AU9+AW9+AY9+BA9+BC9+BE9+BG9+BI9+BK9+BM9) -> 4000 | D9: =SUM(H9+J9+L9+N9+P9+R9+T9+V9+X9+Z9+AB9+AD9+AF9+AJ9+AH9+AL9+AN9+AP9+AR9+AT9+AV9+AX9+AZ9+BB9+BD9+BF9+BH9+BJ9+BL9+BN9) -> 4000 | E9: =C9-D9 -> 0 | G9: 4000 | H9: 0 | I9: 0 | J9: 0 | K9: =I9-J9 -> 0 | L9: 0 | M9: =K9-L9 -> 0 | N9: 0 | O9: =M9-N9 -> 0 | P9: 4000 | Q9: 0 | R9: 0 | S9: 0 | T9: 0 | U9: 0 | V9: 0 | W9: 0 | X9: 0 | Y9: 0 | Z9: 0 | AA9: 0 | AB9: 0 | AC9: 0 | AD9: 0 | AE9: 0 | AF9: 0 | AG9: 0 | AH9: 0 | AI9: 0 | AJ9: 0 | AK9: 0 | AL9: 0 | AM9: 0 | AN9: 0 | AO9: 0 | AP9: 0 | AQ9: 0 | AR9: 0 | AS9: 0 | AT9: 0 | AU9: 0 | AV9: 0 | AW9: 0 | AX9: 0 | AY9: 0 | AZ9: 0 | BA9: 0 | BB9: 0 | BC9: 0 | BD9: 0 | BE9: 0 | BF9: 0 | BG9: 0 | BH9: 0 | BI9: 0 | BJ9: 0 | BK9: 0 | BL9: 0 | BM9: 0 | BN9: 0 | BO9: =G9-H9+I9-J9+K9-L9+M9-N9+O9-P9+Q9-R9+S9-T9+U9-V9+W9-X9+Y9-Z9+AA9-AB9+AC9-AD9+AE9-AF9+AG9-AH9+AI9-AJ9+AK9-AL9+AM9-AN9+AO9-AP9+AQ9-AR9+AS9-AT9+AU9-AV9+AW9-AX9+AY9-AZ9+BA9-BB9+BC9-BD9+BE9-BF9+BG9-BH9+BI9-BJ9+BK9-BL9+BM9-BN9 -> 0 | BP9: 0.75 | BQ9: =C9*BP9 -> 3000 | BR9: =D9*BP9 -> 3000 | BS9: =E9*BP9 -> 0
A10: Gauze Roll | B10: ea | C10: =SUM(G10+I10+K10+M10+O10+Q10+S10+U10+W10+Y10+AA10+AC10+AE10+AG10+AI10+AK10+AM10+AO10+AQ10+AS10+AU10+AW10+AY10+BA10+BC10+BE10+BG10+BI10+BK10+BM10) -> 42 | D10: =SUM(H10+J10+L10+N10+P10+R10+T10+V10+X10+Z10+AB10+AD10+AF10+AJ10+AH10+AL10+AN10+AP10+AR10+AT10+AV10+AX10+AZ10+BB10+BD10+BF10+BH10+BJ10+BL10+BN10) -> 12 | E10: =C10-D10 -> 30 | F10: MG | G10: 12 | H10: 0 | I10: 0 | J10: 0 | K10: =I10-J10 -> 0 | L10: 0 | M10: =K10-L10 -> 0 | N10: 0 | O10: =M10-N10 -> 0 | P10: 12 | Q10: 0 | R10: 0 | S10: 30 | T10: 0 | U10: 0 | V10: 0 | W10: 0 | X10: 0 | Y10: 0 | Z10: 0 | AA10: 0 | AB10: 0 | AC10: 0 | AD10: 0 | AE10: 0 | AF10: 0 | AG10: 0 | AH10: 0 | AI10: 0 | AJ10: 0 | AK10: 0 | AL10: 0 | AM10: 0 | AN10: 0 | AO10: 0 | AP10: 0 | AQ10: 0 | AR10: 0 | AS10: 0 | AT10: 0 | AU10: 0 | AV10: 0 | AW10: 0 | AX10: 0 | AY10: 0 | AZ10: 0 | BA10: 0 | BB10: 0 | BC10: 0 | BD10: 0 | BE10: 0 | BF10: 0 | BG10: 0 | BH10: 0 | BI10: 0 | BJ10: 0 | BK10: 0 | BL10: 0 | BM10: 0 | BN10: 0 | BO10: =G10-H10+I10-J10+K10-L10+M10-N10+O10-P10+Q10-R10+S10-T10+U10-V10+W10-X10+Y10-Z10+AA10-AB10+AC10-AD10+AE10-AF10+AG10-AH10+AI10-AJ10+AK10-AL10+AM10-AN10+AO10-AP10+AQ10-AR10+AS10-AT10+AU10-AV10+AW10-AX10+AY10-AZ10+BA10-BB10+BC10-BD10+BE10-BF10+BG10-BH10+BI10-BJ10+BK10-BL10+BM10-BN10 -> 30 | BP10: 3 | BQ10: =C10*BP10 -> 126 | BR10: =D10*BP10 -> 36 | BS10: =E10*BP10 -> 90
A11: Electrosurgical Pads | B11: ea | C11: =SUM(G11+I11+K11+M11+O11+Q11+S11+U11+W11+Y11+AA11+AC11+AE11+AG11+AI11+AK11+AM11+AO11+AQ11+AS11+AU11+AW11+AY11+BA11+BC11+BE11+BG11+BI11+BK11+BM11) -> 5000 | D11: =SUM(H11+J11+L11+N11+P11+R11+T11+V11+X11+Z11+AB11+AD11+AF11+AJ11+AH11+AL11+AN11+AP11+AR11+AT11+AV11+AX11+AZ11+BB11+BD11+BF11+BH11+BJ11+BL11+BN11) -> 5000 | E11: =C11-D11 -> 0 | G11: 5000 | H11: 0 | I11: 0 | J11: 0 | K11: =I11-J11 -> 0 | L11: 0 | M11: =K11-L11 -> 0 | N11: 0 | O11: =M11-N11 -> 0 | P11: 5000 | Q11: 0 | R11: 0 | S11: 0 | T11: 0 | U11: 0 | V11: 0 | W11: 0 | X11: 0 | Y11: 0 | Z11: 0 | AA11: 0 | AB11: 0 | AC11: 0 | AD11: 0 | AE11: 0 | AF11: 0 | AG11: 0 | AH11: 0 | AI11: 0 | AJ11: 0 | AK11: 0 | AL11: 0 | AM11: 0 | AN11: 0 | AO11: 0 | AP11: 0 | AQ11: 0 | AR11: 0 | AS11: 0 | AT11: 0 | AU11: 0 | AV11: 0 | AW11: 0 | AX11: 0 | AY11: 0 | AZ11: 0 | BA11: 0 | BB11: 0 | BC11: 0 | BD11: 0 | BE11: 0 | BF11: 0 | BG11: 0 | BH11: 0 | BI11: 0 | BJ11: 0 | BK11: 0 | BL11: 0 | BM11: 0 | BN11: 0 | BO11: =G11-H11+I11-J11+K11-L11+M11-N11+O11-P11+Q11-R11+S11-T11+U11-V11+W11-X11+Y11-Z11+AA11-AB11+AC11-AD11+AE11-AF11+AG11-AH11+AI11-AJ11+AK11-AL11+AM11-AN11+AO11-AP11+AQ11-AR11+AS11-AT11+AU11-AV11+AW11-AX11+AY11-AZ11+BA11-BB11+BC11-BD11+BE11-BF11+BG11-BH11+BI11-BJ11+BK11-BL11+BM11-BN11 -> 0 | BP11: 1 | BQ11: =C11*BP11 -> 5000 | BR11: =D11*BP11 -> 5000 | BS11: =E11*BP11 -> 0
A12: Gauze Bandage | B12: ea | C12: =SUM(G12+I12+K12+M12+O12+Q12+S12+U12+W12+Y12+AA12+AC12+AE12+AG12+AI12+AK12+AM12+AO12+AQ12+AS12+AU12+AW12+AY12+BA12+BC12+BE12+BG12+BI12+BK12+BM12) -> 1440 | D12: =SUM(H12+J12+L12+N12+P12+R12+T12+V12+X12+Z12+AB12+AD12+AF12+AJ12+AH12+AL12+AN12+AP12+AR12+AT12+AV12+AX12+AZ12+BB12+BD12+BF12+BH12+BJ12+BL12+BN12) -> 1440 | E12: =C12-D12 -> 0 | G12: 1440 | H12: 0 | I12: 0 | J12: 0 | K12: =I12-J12 -> 0 | L12: 0 | M12: =K12-L12 -> 0 | N12: 0 | O12: =M12-N12 -> 0 | P12: 1440 | Q12: 0 | R12: 0 | S12: 0 | T12: 0 | U12: 0 | V12: 0 | W12: 0 | X12: 0 | Y12: 0 | Z12: 0 | AA12: 0 | AB12: 0 | AC12: 0 | AD12: 0 | AE12: 0 | AF12: 0 | AG12: 0 | AH12: 0 | AI12: 0 | AJ12: 0 | AK12: 0 | AL12: 0 | AM12: 0 | AN12: 0 | AO12: 0 | AP12: 0 | AQ12: 0 | AR12: 0 | AS12: 0 | AT12: 0 | AU12: 0 | AV12: 0 | AW12: 0 | AX12: 0 | AY12: 0 | AZ12: 0 | BA12: 0 | BB12: 0 | BC12: 0 | BD12: 0 | BE12: 0 | BF12: 0 | BG12: 0 | BH12: 0 | BI12: 0 | BJ12: 0 | BK12: 0 | BL12: 0 | BM12: 0 | BN12: 0 | BO12: =G12-H12+I12-J12+K12-L12+M12-N12+O12-P12+Q12-R12+S12-T12+U12-V12+W12-X12+Y12-Z12+AA12-AB12+AC12-AD12+AE12-AF12+AG12-AH12+AI12-AJ12+AK12-AL12+AM12-AN12+AO12-AP12+AQ12-AR12+AS12-AT12+AU12-AV12+AW12-AX12+AY12-AZ12+BA12-BB12+BC12-BD12+BE12-BF12+BG12-BH12+BI12-BJ12+BK12-BL12+BM12-BN12 -> 0 | BP12: 1 | BQ12: =C12*BP12 -> 1440 | BR12: =D12*BP12 -> 1440 | BS12: =E12*BP12 -> 0
A13: Oxygen Supply Tubing | B13: ea | C13: =SUM(G13+I13+K13+M13+O13+Q13+S13+U13+W13+Y13+AA13+AC13+AE13+AG13+AI13+AK13+AM13+AO13+AQ13+AS13+AU13+AW13+AY13+BA13+BC13+BE13+BG13+BI13+BK13+BM13) -> 500 | D13: =SUM(H13+J13+L13+N13+P13+R13+T13+V13+X13+Z13+AB13+AD13+AF13+AJ13+AH13+AL13+AN13+AP13+AR13+AT13+AV13+AX13+AZ13+BB13+BD13+BF13+BH13+BJ13+BL13+BN13) -> 500 | E13: =C13-D13 -> 0 | G13: 500 | H13: 0 | I13: 0 | J13: 0 | K13: =I13-J13 -> 0 | L13: 0 | M13: =K13-L13 -> 0 | N13: 0 | O13: =M13-N13 -> 0 | P13: 500 | Q13: 0 | R13: 0 | S13: 0 | T13: 0 | U13: 0 | V13: 0 | W13: 0 | X13: 0 | Y13: 0 | Z13: 0 | AA13: 0 | AB13: 0 | AC13: 0 | AD13: 0 | AE13: 0 | AF13: 0 | AG13: 0 | AH13: 0 | AI13: 0 | AJ13: 0 | AK13: 0 | AL13: 0 | AM13: 0 | AN13: 0 | AO13: 0 | AP13: 0 | AQ13: 0 | AR13: 0 | AS13: 0 | AT13: 0 | AU13: 0 | AV13: 0 | AW13: 0 | AX13: 0 | AY13: 0 | AZ13: 0 | BA13: 0 | BB13: 0 | BC13: 0 | BD13: 0 | BE13: 0 | BF13: 0 | BG13: 0 | BH13: 0 | BI13: 0 | BJ13: 0 | BK13: 0 | BL13: 0 | BM13: 0 | BN13: 0 | BO13: =G13-H13+I13-J13+K13-L13+M13-N13+O13-P13+Q13-R13+S13-T13+U13-V13+W13-X13+Y13-Z13+AA13-AB13+AC13-AD13+AE13-AF13+AG13-AH13+AI13-AJ13+AK13-AL13+AM13-AN13+AO13-AP13+AQ13-AR13+AS13-AT13+AU13-AV13+AW13-AX13+AY13-AZ13+BA13-BB13+BC13-BD13+BE13-BF13+BG13-BH13+BI13-BJ13+BK13-BL13+BM13-BN13 -> 0 | BP13: 6 | BQ13: =C13*BP13 -> 3000 | BR13: =D13*BP13 -> 3000 | BS13: =E13*BP13 -> 0
A14: Blood Sets | B14: ea | C14: =SUM(G14+I14+K14+M14+O14+Q14+S14+U14+W14+Y14+AA14+AC14+AE14+AG14+AI14+AK14+AM14+AO14+AQ14+AS14+AU14+AW14+AY14+BA14+BC14+BE14+BG14+BI14+BK14+BM14) -> 1088 | D14: =SUM(H14+J14+L14+N14+P14+R14+T14+V14+X14+Z14+AB14+AD14+AF14+AJ14+AH14+AL14+AN14+AP14+AR14+AT14+AV14+AX14+AZ14+BB14+BD14+BF14+BH14+BJ14+BL14+BN14) -> 1088 | E14: =C14-D14 -> 0 | G14: 1088 | H14: 0 | I14: 0 | J14: 0 | K14: =I14-J14 -> 0 | L14: 0 | M14: =K14-L14 -> 0 | N14: 0 | O14: =M14-N14 -> 0 | P14: 1088 | Q14: 0 | R14: 0 | S14: 0 | T14: 0 | U14: 0 | V14: 0 | W14: 0 | X14: 0 | Y14: 0 | Z14: 0 | AA14: 0 | AB14: 0 | AC14: 0 | AD14: 0 | AE14: 0 | AF14: 0 | AG14: 0 | AH14: 0 | AI14: 0 | AJ14: 0 | AK14: 0 | AL14: 0 | AM14: 0 | AN14: 0 | AO14: 0 | AP14: 0 | AQ14: 0 | AR14: 0 | AS14: 0 | AT14: 0 | AU14: 0 | AV14: 0 | AW14: 0 | AX14: 0 | AY14: 0 | AZ14: 0 | BA14: 0 | BB14: 0 | BC14: 0 | BD14: 0 | BE14: 0 | BF14: 0 | BG14: 0 | BH14: 0 | BI14: 0 | BJ14: 0 | BK14: 0 | BL14: 0 | BM14: 0 | BN14: 0 | BO14: =G14-H14+I14-J14+K14-L14+M14-N14+O14-P14+Q14-R14+S14-T14+U14-V14+W14-X14+Y14-Z14+AA14-AB14+AC14-AD14+AE14-AF14+AG14-AH14+AI14-AJ14+AK14-AL14+AM14-AN14+AO14-AP14+AQ14-AR14+AS14-AT14+AU14-AV14+AW14-AX14+AY14-AZ14+BA14-BB14+BC14-BD14+BE14-BF14+BG14-BH14+BI14-BJ14+BK14-BL14+BM14-BN14 -> 0 | BP14: 30 | BQ14: =C14*BP14 -> 32640 | BR14: =D14*BP14 -> 32640 | BS14: =E14*BP14 -> 0
A15: Tourniquets | B15: ea | C15: =SUM(G15+I15+K15+M15+O15+Q15+S15+U15+W15+Y15+AA15+AC15+AE15+AG15+AI15+AK15+AM15+AO15+AQ15+AS15+AU15+AW15+AY15+BA15+BC15+BE15+BG15+BI15+BK15+BM15) -> 25000 | D15: =SUM(H15+J15+L15+N15+P15+R15+T15+V15+X15+Z15+AB15+AD15+AF15+AJ15+AH15+AL15+AN15+AP15+AR15+AT15+AV15+AX15+AZ15+BB15+BD15+BF15+BH15+BJ15+BL15+BN15) -> 25000 | E15: =C15-D15 -> 0 | G15: 25000 | H15: 0 | I15: 0 | J15: 0 | K15: =I15-J15 -> 0 | L15: 0 | M15: =K15-L15 -> 0 | N15: 0 | O15: =M15-N15 -> 0 | P15: 25000 | Q15: 0 | R15: 0 | S15: 0 | T15: 0 | U15: 0 | V15: 0 | W15: 0 | X15: 0 | Y15: 0 | Z15: 0 | AA15: 0 | AB15: 0 | AC15: 0 | AD15: 0 | AE15: 0 | AF15: 0 | AG15: 0 | AH15: 0 | AI15: 0 | AJ15: 0 | AK15: 0 | AL15: 0 | AM15: 0 | AN15: 0 | AO15: 0 | AP15: 0 | AQ15: 0 | AR15: 0 | AS15: 0 | AT15: 0 | AU15: 0 | AV15: 0 | AW15: 0 | AX15: 0 | AY15: 0 | AZ15: 0 | BA15: 0 | BB15: 0 | BC15: 0 | BD15: 0 | BE15: 0 | BF15: 0 | BG15: 0 | BH15: 0 | BI15: 0 | BJ15: 0 | BK15: 0 | BL15: 0 | BM15: 0 | BN15: 0 | BO15: =G15-H15+I15-J15+K15-L15+M15-N15+O15-P15+Q15-R15+S15-T15+U15-V15+W15-X15+Y15-Z15+AA15-AB15+AC15-AD15+AE15-AF15+AG15-AH15+AI15-AJ15+AK15-AL15+AM15-AN15+AO15-AP15+AQ15-AR15+AS15-AT15+AU15-AV15+AW15-AX15+AY15-AZ15+BA15-BB15+BC15-BD15+BE15-BF15+BG15-BH15+BI15-BJ15+BK15-BL15+BM15-BN15 -> 0 | BP15: 0.36 | BQ15: =C15*BP15 -> 9000 | BR15: =D15*BP15 -> 9000 | BS15: =E15*BP15 -> 0
A16: Nebulizer | B16: ea | C16: =SUM(G16+I16+K16+M16+O16+Q16+S16+U16+W16+Y16+AA16+AC16+AE16+AG16+AI16+AK16+AM16+AO16+AQ16+AS16+AU16+AW16+AY16+BA16+BC16+BE16+BG16+BI16+BK16+BM16) -> 100 | D16: =SUM(H16+J16+L16+N16+P16+R16+T16+V16+X16+Z16+AB16+AD16+AF16+AJ16+AH16+AL16+AN16+AP16+AR16+AT16+AV16+AX16+AZ16+BB16+BD16+BF16+BH16+BJ16+BL16+BN16) -> 100 | E16: =C16-D16 -> 0 | G16: 100 | H16: 0 | I16: 0 | J16: 0 | K16: =I16-J16 -> 0 | L16: 0 | M16: =K16-L16 -> 0 | N16: 0 | O16: =M16-N16 -> 0 | P16: 100 | Q16: 0 | R16: 0 | S16: 0 | T16: 0 | U16: 0 | V16: 0 | W16: 0 | X16: 0 | Y16: 0 | Z16: 0 | AA16: 0 | AB16: 0 | AC16: 0 | AD16: 0 | AE16: 0 | AF16: 0 | AG16: 0 | AH16: 0 | AI16: 0 | AJ16: 0 | AK16: 0 | AL16: 0 | AM16: 0 | AN16: 0 | AO16: 0 | AP16: 0 | AQ16: 0 | AR16: 0 | AS16: 0 | AT16: 0 | AU16: 0 | AV16: 0 | AW16: 0 | AX16: 0 | AY16: 0 | AZ16: 0 | BA16: 0 | BB16: 0 | BC16: 0 | BD16: 0 | BE16: 0 | BF16: 0 | BG16: 0 | BH16: 0 | BI16: 0 | BJ16: 0 | BK16: 0 | BL16: 0 | BM16: 0 | BN16: 0 | BO16: =G16-H16+I16-J16+K16-L16+M16-N16+O16-P16+Q16-R16+S16-T16+U16-V16+W16-X16+Y16-Z16+AA16-AB16+AC16-AD16+AE16-AF16+AG16-AH16+AI16-AJ16+AK16-AL16+AM16-AN16+AO16-AP16+AQ16-AR16+AS16-AT16+AU16-AV16+AW16-AX16+AY16-AZ16+BA16-BB16+BC16-BD16+BE16-BF16+BG16-BH16+BI16-BJ16+BK16-BL16+BM16-BN16 -> 0 | BP16: 40 | BQ16: =C16*BP16 -> 4000 | BR16: =D16*BP16 -> 4000 | BS16: =E16*BP16 -> 0
A17: Aerosol Elongated Mask | B17: ea | C17: =SUM(G17+I17+K17+M17+O17+Q17+S17+U17+W17+Y17+AA17+AC17+AE17+AG17+AI17+AK17+AM17+AO17+AQ17+AS17+AU17+AW17+AY17+BA17+BC17+BE17+BG17+BI17+BK17+BM17) -> 300 | D17: =SUM(H17+J17+L17+N17+P17+R17+T17+V17+X17+Z17+AB17+AD17+AF17+AJ17+AH17+AL17+AN17+AP17+AR17+AT17+AV17+AX17+AZ17+BB17+BD17+BF17+BH17+BJ17+BL17+BN17) -> 300 | E17: =C17-D17 -> 0 | G17: 300 | H17: 0 | I17: 0 | J17: 0 | K17: =I17-J17 -> 0 | L17: 0 | M17: =K17-L17 -> 0 | N17: 0 | O17: =M17-N17 -> 0 | P17: 300 | Q17: 0 | R17: 0 | S17: 0 | T17: 0 | U17: 0 | V17: 0 | W17: 0 | X17: 0 | Y17: 0 | Z17: 0 | AA17: 0 | AB17: 0 | AC17: 0 | AD17: 0 | AE17: 0 | AF17: 0 | AG17: 0 | AH17: 0 | AI17: 0 | AJ17: 0 | AK17: 0 | AL17: 0 | AM17: 0 | AN17: 0 | AO17: 0 | AP17: 0 | AQ17: 0 | AR17: 0 | AS17: 0 | AT17: 0 | AU17: 0 | AV17: 0 | AW17: 0 | AX17: 0 | AY17: 0 | AZ17: 0 | BA17: 0 | BB17: 0 | BC17: 0 | BD17: 0 | BE17: 0 | BF17: 0 | BG17: 0 | BH17: 0 | BI17: 0 | BJ17: 0 | BK17: 0 | BL17: 0 | BM17: 0 | BN17: 0 | BO17: =G17-H17+I17-J17+K17-L17+M17-N17+O17-P17+Q17-R17+S17-T17+U17-V17+W17-X17+Y17-Z17+AA17-AB17+AC17-AD17+AE17-AF17+AG17-AH17+AI17-AJ17+AK17-AL17+AM17-AN17+AO17-AP17+AQ17-AR17+AS17-AT17+AU17-AV17+AW17-AX17+AY17-AZ17+BA17-BB17+BC17-BD17+BE17-BF17+BG17-BH17+BI17-BJ17+BK17-BL17+BM17-BN17 -> 0 | BP17: 9 | BQ17: =C17*BP17 -> 2700 | BR17: =D17*BP17 -> 2700 | BS17: =E17*BP17 -> 0
A18: Disposable Bed Sheet | B18: ea | C18: =SUM(G18+I18+K18+M18+O18+Q18+S18+U18+W18+Y18+AA18+AC18+AE18+AG18+AI18+AK18+AM18+AO18+AQ18+AS18+AU18+AW18+AY18+BA18+BC18+BE18+BG18+BI18+BK18+BM18) -> 6000 | D18: =SUM(H18+J18+L18+N18+P18+R18+T18+V18+X18+Z18+AB18+AD18+AF18+AJ18+AH18+AL18+AN18+AP18+AR18+AT18+AV18+AX18+AZ18+BB18+BD18+BF18+BH18+BJ18+BL18+BN18) -> 6000 | E18: =C18-D18 -> 0 | G18: 6000 | H18: 0 | I18: 0 | J18: 0 | K18: =I18-J18 -> 0 | L18: 0 | M18: =K18-L18 -> 0 | N18: 0 | O18: =M18-N18 -> 0 | P18: 6000 | Q18: 0 | R18: 0 | S18: 0 | T18: 0 | U18: 0 | V18: 0 | W18: 0 | X18: 0 | Y18: 0 | Z18: 0 | AA18: 0 | AB18: 0 | AC18: 0 | AD18: 0 | AE18: 0 | AF18: 0 | AG18: 0 | AH18: 0 | AI18: 0 | AJ18: 0 | AK18: 0 | AL18: 0 | AM18: 0 | AN18: 0 | AO18: 0 | AP18: 0 | AQ18: 0 | AR18: 0 | AS18: 0 | AT18: 0 | AU18: 0 | AV18: 0 | AW18: 0 | AX18: 0 | AY18: 0 | AZ18: 0 | BA18: 0 | BB18: 0 | BC18: 0 | BD18: 0 | BE18: 0 | BF18: 0 | BG18: 0 | BH18: 0 | BI18: 0 | BJ18: 0 | BK18: 0 | BL18: 0 | BM18: 0 | BN18: 0 | BO18: =G18-H18+I18-J18+K18-L18+M18-N18+O18-P18+Q18-R18+S18-T18+U18-V18+W18-X18+Y18-Z18+AA18-AB18+AC18-AD18+AE18-AF18+AG18-AH18+AI18-AJ18+AK18-AL18+AM18-AN18+AO18-AP18+AQ18-AR18+AS18-AT18+AU18-AV18+AW18-AX18+AY18-AZ18+BA18-BB18+BC18-BD18+BE18-BF18+BG18-BH18+BI18-BJ18+BK18-BL18+BM18-BN18 -> 0 | BP18: 1.5 | BQ18: =C18*BP18 -> 9000 | BR18: =D18*BP18 -> 9000 | BS18: =E18*BP18 -> 0
A19: Medical Box(Assorted items ) | B19: ea | C19: =SUM(G19+I19+K19+M19+O19+Q19+S19+U19+W19+Y19+AA19+AC19+AE19+AG19+AI19+AK19+AM19+AO19+AQ19+AS19+AU19+AW19+AY19+BA19+BC19+BE19+BG19+BI19+BK19+BM19) -> 30 | D19: =SUM(H19+J19+L19+N19+P19+R19+T19+V19+X19+Z19+AB19+AD19+AF19+AJ19+AH19+AL19+AN19+AP19+AR19+AT19+AV19+AX19+AZ19+BB19+BD19+BF19+BH19+BJ19+BL19+BN19) -> 30 | E19: =C19-D19 -> 0 | G19: 30 | H19: 0 | I19: 0 | J19: 0 | K19: =I19-J19 -> 0 | L19: 0 | M19: =K19-L19 -> 0 | N19: 0 | O19: =M19-N19 -> 0 | P19: 30 | Q19: 0 | R19: 0 | S19: 0 | T19: 0 | U19: 0 | V19: 0 | W19: 0 | X19: 0 | Y19: 0 | Z19: 0 | AA19: 0 | AB19: 0 | AC19: 0 | AD19: 0 | AE19: 0 | AF19: 0 | AG19: 0 | AH19: 0 | AI19: 0 | AJ19: 0 | AK19: 0 | AL19: 0 | AM19: 0 | AN19: 0 | AO19: 0 | AP19: 0 | AQ19: 0 | AR19: 0 | AS19: 0 | AT19: 0 | AU19: 0 | AV19: 0 | AW19: 0 | AX19: 0 | AY19: 0 | AZ19: 0 | BA19: 0 | BB19: 0 | BC19: 0 | BD19: 0 | BE19: 0 | BF19: 0 | BG19: 0 | BH19: 0 | BI19: 0 | BJ19: 0 | BK19: 0 | BL19: 0 | BM19: 0 | BN19: 0 | BO19: =G19-H19+I19-J19+K19-L19+M19-N19+O19-P19+Q19-R19+S19-T19+U19-V19+W19-X19+Y19-Z19+AA19-AB19+AC19-AD19+AE19-AF19+AG19-AH19+AI19-AJ19+AK19-AL19+AM19-AN19+AO19-AP19+AQ19-AR19+AS19-AT19+AU19-AV19+AW19-AX19+AY19-AZ19+BA19-BB19+BC19-BD19+BE19-BF19+BG19-BH19+BI19-BJ19+BK19-BL19+BM19-BN19 -> 0 | BP19: 30 | BQ19: =C19*BP19 -> 900 | BR19: =D19*BP19 -> 900 | BS19: =E19*BP19 -> 0
A20: Wash Basin | B20: ea | C20: =SUM(G20+I20+K20+M20+O20+Q20+S20+U20+W20+Y20+AA20+AC20+AE20+AG20+AI20+AK20+AM20+AO20+AQ20+AS20+AU20+AW20+AY20+BA20+BC20+BE20+BG20+BI20+BK20+BM20) -> 600 | D20: =SUM(H20+J20+L20+N20+P20+R20+T20+V20+X20+Z20+AB20+AD20+AF20+AJ20+AH20+AL20+AN20+AP20+AR20+AT20+AV20+AX20+AZ20+BB20+BD20+BF20+BH20+BJ20+BL20+BN20) -> 600 | E20: =C20-D20 -> 0 | G20: 600 | H20: 0 | I20: 0 | J20: 0 | K20: =I20-J20 -> 0 | L20: 0 | M20: =K20-L20 -> 0 | N20: 0 | O20: =M20-N20 -> 0 | P20: 600 | Q20: 0 | R20: 0 | S20: 0 | T20: 0 | U20: 0 | V20: 0 | W20: 0 | X20: 0 | Y20: 0 | Z20: 0 | AA20: 0 | AB20: 0 | AC20: 0 | AD20: 0 | AE20: 0 | AF20: 0 | AG20: 0 | AH20: 0 | AI20: 0 | AJ20: 0 | AK20: 0 | AL20: 0 | AM20: 0 | AN20: 0 | AO20: 0 | AP20: 0 | AQ20: 0 | AR20: 0 | AS20: 0 | AT20: 0 | AU20: 0 | AV20: 0 | AW20: 0 | AX20: 0 | AY20: 0 | AZ20: 0 | BA20: 0 | BB20: 0 | BC20: 0 | BD20: 0 | BE20: 0 | BF20: 0 | BG20: 0 | BH20: 0 | BI20: 0 | BJ20: 0 | BK20: 0 | BL20: 0 | BM20: 0 | BN20: 0 | BO20: =G20-H20+I20-J20+K20-L20+M20-N20+O20-P20+Q20-R20+S20-T20+U20-V20+W20-X20+Y20-Z20+AA20-AB20+AC20-AD20+AE20-AF20+AG20-AH20+AI20-AJ20+AK20-AL20+AM20-AN20+AO20-AP20+AQ20-AR20+AS20-AT20+AU20-AV20+AW20-AX20+AY20-AZ20+BA20-BB20+BC20-BD20+BE20-BF20+BG20-BH20+BI20-BJ20+BK20-BL20+BM20-BN20 -> 0 | BP20: 3 | BQ20: =C20*BP20 -> 1800 | BR20: =D20*BP20 -> 1800 | BS20: =E20*BP20 -> 0
A21: Cold Pack | B21: ea | C21: =SUM(G21+I21+K21+M21+O21+Q21+S21+U21+W21+Y21+AA21+AC21+AE21+AG21+AI21+AK21+AM21+AO21+AQ21+AS21+AU21+AW21+AY21+BA21+BC21+BE21+BG21+BI21+BK21+BM21) -> 24 | D21: =SUM(H21+J21+L21+N21+P21+R21+T21+V21+X21+Z21+AB21+AD21+AF21+AJ21+AH21+AL21+AN21+AP21+AR21+AT21+AV21+AX21+AZ21+BB21+BD21+BF21+BH21+BJ21+BL21+BN21) -> 24 | E21: =C21-D21 -> 0 | G21: 24 | H21: 0 | I21: 0 | J21: 0 | K21: =I21-J21 -> 0 | L21: 0 | M21: =K21-L21 -> 0 | N21: 0 | O21: =M21-N21 -> 0 | P21: 24 | Q21: 0 | R21: 0 | S21: 0 | T21: 0 | U21: 0 | V21: 0 | W21: 0 | X21: 0 | Y21: 0 | Z21: 0 | AA21: 0 | AB21: 0 | AC21: 0 | AD21: 0 | AE21: 0 | AF21: 0 | AG21: 0 | AH21: 0 | AI21: 0 | AJ21: 0 | AK21: 0 | AL21: 0 | AM21: 0 | AN21: 0 | AO21: 0 | AP21: 0 | AQ21: 0 | AR21: 0 | AS21: 0 | AT21: 0 | AU21: 0 | AV21: 0 | AW21: 0 | AX21: 0 | AY21: 0 | AZ21: 0 | BA21: 0 | BB21: 0 | BC21: 0 | BD21: 0 | BE21: 0 | BF21: 0 | BG21: 0 | BH21: 0 | BI21: 0 | BJ21: 0 | BK21: 0 | BL21: 0 | BM21: 0 | BN21: 0 | BO21: =G21-H21+I21-J21+K21-L21+M21-N21+O21-P21+Q21-R21+S21-T21+U21-V21+W21-X21+Y21-Z21+AA21-AB21+AC21-AD21+AE21-AF21+AG21-AH21+AI21-AJ21+AK21-AL21+AM21-AN21+AO21-AP21+AQ21-AR21+AS21-AT21+AU21-AV21+AW21-AX21+AY21-AZ21+BA21-BB21+BC21-BD21+BE21-BF21+BG21-BH21+BI21-BJ21+BK21-BL21+BM21-BN21 -> 0 | BP21: 1 | BQ21: =C21*BP21 -> 24 | BR21: =D21*BP21 -> 24 | BS21: =E21*BP21 -> 0
